Workbook

Sheet VŠECHNY AKCE=

Sheet Přehled akce
A1: PŘEHLED AKCE
A2: Junák - středisko Milana Genserka Brno (622.08)
A4: Název akce: | J4: Kód akce:
A5: Datum konání akce: | J5: Rok:
A6: Vedoucí akce: | J6: Počet dnů:
A7: Hospodář akce:
A8: Počet účastníků: | J8: Počet účastnických osobodnů: | K8: ='Seznam účastníků'!H67 -> 0
A9: Počet pořadatelů | J9: Počet celkových osobodnů: | K9: =(D9+D8)*K6 -> 0
A11: Přehled nutných dokumentů | F11: Stav po revizi | J11: Podpis
A12: £ | B12: seznam výdajů a příjmů (vždy)
A13: £ | B13: seznam účastníků s platbou (vždy)
A14: £ | B14: rozpočet akce (u velkých akcí)
A15: £ | B15: vyúčtování dotací
A16: £ | B16: smlouvy o proplácení cestovních náhrad
A17: £ | B17: předávací protokoly na odměny
A19: Přehled výdajů akce
A20: Kód | B20: MD | C20: Položka | F20: D | H20: Hotově | I20: D | K20: Převodem | L20: VÝDAJE CELKEM
A21: náj | B21: 518.310 | C21: Nájemné | F21: 211. | G21: =$K$4 -> 0 | H21: ='Příjmy a výdaje'!AA445 -> 0 | I21: 221. | J21: 1 | K21: ='Příjmy a výdaje'!AA27 -> 0 | L21: =H21+K21 -> 0
A22: pot | B22: 501.110 | C22: Potraviny | F22: 211. | G22: =$K$4 -> 0 | H22: ='Příjmy a výdaje'!S445 -> 0 | I22: 221. | J22: 1 | K22: ='Příjmy a výdaje'!S27 -> 0 | L22: =H22+K22 -> 0
A23: dop | B23: 518.210 | C23: Doprava osobní na akcích | F23: 211. | G23: =$K$4 -> 0 | H23: ='Příjmy a výdaje'!Y445 -> 0 | I23: 221. | J23: 1 | K23: ='Příjmy a výdaje'!Y27 -> 0 | L23: =H23+K23 -> 0
A24: nák | B24: 518.220 | C24: Doprava nákladní | F24: 211. | G24: =$K$4 -> 0 | H24: ='Příjmy a výdaje'!Z445 -> 0 | I24: 221. | J24: 1 | K24: ='Příjmy a výdaje'!Z27 -> 0 | L24: =H24+K24 -> 0
A25: ces | B25: 512 | C25: Cestovné | F25: 211. | G25: =$K$4 -> 0 | H25: ='Příjmy a výdaje'!V445 -> 0 | I25: 221. | J25: 1 | K25: ='Příjmy a výdaje'!V27 -> 0 | L25: =H25+K25 -> 0
A26: vst | B26: 518.310 | C26: Vstupné | F26: 211. | G26: =$K$4 -> 0 | H26: ='Příjmy a výdaje'!AC445 -> 0 | I26: 221. | J26: 1 | K26: ='Příjmy a výdaje'!AC27 -> 0 | L26: =H26+K26 -> 0
A27: mat | B27: 501.210 | C27: Materiál na akce | F27: 211. | G27: =$K$4 -> 0 | H27: ='Příjmy a výdaje'!R445 -> 0 | I27: 221. | J27: 1 | K27: ='Příjmy a výdaje'!R27 -> 0 | L27: =H27+K27 -> 0
A28: vyb | B28: 501.310 | C28: Vybavení vedené v operativní evidenci | F28: 211. | G28: =$K$4 -> 0 | H28: ='Příjmy a výdaje'!P445 -> 0 | I28: 221. | J28: 1 | K28: ='Příjmy a výdaje'!P27 -> 0 | L28: =H28+K28 -> 0
A29: mtv | B29: 501.320 | C29: Materiál pro tvorbu vybavení | F29: 211. | G29: =$K$4 -> 0 | H29: ='Příjmy a výdaje'!Q445 -> 0 | I29: 221. | J29: 1 | K29: ='Příjmy a výdaje'!Q27 -> 0 | L29: =H29+K29 -> 0
A30: táb | B30: 501.530 | C30: Materiál na opravu a údržbu tábořišť | F30: 211. | G30: =$K$4 -> 0 | H30: ='Příjmy a výdaje'!T445 -> 0 | I30: 221. | J30: 1 | K30: ='Příjmy a výdaje'!T27 -> 0 | L30: =H30+K30 -> 0
A31: oma | B31: 501.900 | C31: Ostatní materiál | F31: 211. | G31: =$K$4 -> 0 | H31: ='Příjmy a výdaje'!U445 -> 0 | I31: 221. | J31: 1 | K31: ='Příjmy a výdaje'!U27 -> 0 | L31: =H31+K31 -> 0
A32: poš | B32: 518.410 | C32: Poštovné | F32: 211. | G32: =$K$4 -> 0 | H32: ='Příjmy a výdaje'!W445 -> 0 | I32: 221. | J32: 1 | K32: ='Příjmy a výdaje'!W27 -> 0 | L32: =H32+K32 -> 0
A33: kop | B33: 518.510 | C33: Kopírování | F33: 211. | G33: =$K$4 -> 0 | H33: ='Příjmy a výdaje'!AD445 -> 0 | I33: 221. | J33: 1 | K33: ='Příjmy a výdaje'!AD27 -> 0 | L33: =H33+K33 -> 0
A34: tel | B34: 518.610 | C34: Telekomunikační náhrady | F34: 211. | G34: =$K$4 -> 0 | H34: ='Příjmy a výdaje'!X445 -> 0 | I34: 221. | J34: 1 | K34: ='Příjmy a výdaje'!X27 -> 0 | L34: =H34+K34 -> 0
A35: půj | B35: 518.120 | C35: Půjčovné | F35: 211. | G35: =$K$4 -> 0 | H35: ='Příjmy a výdaje'!AB445 -> 0 | I35: 221. | J35: 1 | K35: ='Příjmy a výdaje'!AB27 -> 0 | L35: =H35+K35 -> 0
A36: osl | B36: 518.900 | C36: Ostatní služby | F36: 211. | G36: =$K$4 -> 0 | H36: ='Příjmy a výdaje'!AE445 -> 0 | I36: 221. | J36: 1 | K36: ='Příjmy a výdaje'!AE27 -> 0 | L36: =H36+K36 -> 0
C37: Výdaje celkem | F37: 211. | G37: =$K$4 -> 0 | H37: =SUM(H21:H36) -> 0 | I37: 221. | J37: 1 | K37: =SUM(K21:K36) -> 0 | L37: =SUM(L21:L36) -> 0
A39: Přehled příjmů akce
A40: Kód | B40: D | C40: Položka | F40: MD | H40: Hotově | I40: MD | K40: Převodem | L40: PŘÍJMY CELKEM
A41: pří | B41: 649.100 | C41: Příjmy od účastníků | F41: 211. | G41: =$K$4 -> 0 | H41: ='Příjmy a výdaje'!AI445 -> 0 | I41: 221. | J41: 1 | K41: ='Příjmy a výdaje'!AI27 -> 0 | L41: =H41+K41 -> 0
A42: dot | B42: 681.x | C42: Dotace | F42: 211. | G42: =$K$4 -> 0 | H42: ='Příjmy a výdaje'!AJ445 -> 0 | I42: 221. | J42: 1 | K42: ='Příjmy a výdaje'!AJ27 -> 0 | L42: =H42+K42 -> 0
A43: opř | C43: Ostatní příjmy | F43: 211. | G43: =$K$4 -> 0 | H43: ='Příjmy a výdaje'!AK445 -> 0 | I43: 221. | J43: 1 | K43: ='Příjmy a výdaje'!AK27 -> 0 | L43: =H43+K43 -> 0
C44: Příjmy celkem | F44: 211. | G44: =$K$4 -> 0 | H44: =SUM(H41:H43) -> 0 | I44: 221. | J44: 1 | K44: =SUM(K41:K43) -> 0 | L44: =SUM(L41:L43) -> 0
...

Sheet Příjmy a výdaje
B1: PŘÍJMY A VÝDAJE AKCE
B2: Název akce: | C2: ='Přehled akce'!D4 -> 0
B4: BEZHOTOVOSTNÍ PLATBY (příjmy i výdaje, bez záloh)
B5: Položka | C5: Částka | D5: Kód | E5: Datum platby | F5: Poznámka | G5: Dotováno | J5: Kontrola | P5: vyb | Q5: mtv | R5: mat | S5: pot | T5: táb | U5: oma | V5: ces | W5: poš | X5: tel | Y5: dop | Z5: nák | AA5: náj | AB5: půj | AC5: vst | AD5: kop | AE5: osl | AF5: vra | AG5: zho | AH5: zbú | AI5: pří | AJ5: dot | AK5: opř | AL5: součet
A6: 1 | J6: =IF(AL6=C6,IF(AL6=0,"-","ok"),"chyba") -> - | P6: =VALUE(IF($D6="vyb",$C6,0))+VALUE(IF($H6="vyb",$G6,0)) -> 0 | Q6: =VALUE(IF($D6="mtv",$C6,0))+VALUE(IF($H6="mtv",$G6,0)) -> 0 | R6: =VALUE(IF($D6="mat",$C6,0))+VALUE(IF($H6="mat",$G6,0)) -> 0 | S6: =VALUE(IF($D6="pot",$C6,0))+VALUE(IF($H6="pot",$G6,0)) -> 0 | T6: =VALUE(IF($D6="táb",$C6,0))+VALUE(IF($H6="táb",$G6,0)) -> 0 | U6: =VALUE(IF($D6="oma",$C6,0))+VALUE(IF($H6="oma",$G6,0)) -> 0 | V6: =VALUE(IF($D6="ces",$C6,0))+VALUE(IF($H6="ces",$G6,0)) -> 0 | W6: =VALUE(IF($D6="poš",$C6,0))+VALUE(IF($H6="poš",$G6,0)) -> 0 | X6: =VALUE(IF($D6="tel",$C6,0))+VALUE(IF($H6="tel",$G6,0)) -> 0 | Y6: =VALUE(IF($D6="dop",$C6,0))+VALUE(IF($H6="dop",$G6,0)) -> 0 | Z6: =VALUE(IF($D6="nák",$C6,0))+VALUE(IF($H6="nák",$G6,0)) -> 0 | AA6: =VALUE(IF($D6="náj",$C6,0))+VALUE(IF($H6="náj",$G6,0)) -> 0 | AB6: =VALUE(IF($D6="půj",$C6,0))+VALUE(IF($H6="půj",$G6,0)) -> 0 | AC6: =VALUE(IF($D6="vst",$C6,0))+VALUE(IF($H6="vst",$G6,0)) -> 0 | AD6: =VALUE(IF($D6="kop",$C6,0))+VALUE(IF($H6="kop",$G6,0)) -> 0 | AE6: =VALUE(IF($D6="osl",$C6,0))+VALUE(IF($H6="osl",$G6,0)) -> 0 | AF6: =VALUE(IF($D6="vra",$C6,0))+VALUE(IF($H6="vra",$G6,0)) -> 0 | AG6: =VALUE(IF($D6="zho",$C6,0))+VALUE(IF($H6="zho",$G6,0)) -> 0 | AH6: =VALUE(IF($D6="zbú",$C6,0))+VALUE(IF($H6="zbú",$G6,0)) -> 0 | AI6: =VALUE(IF($D6="pří",$C6,0))+VALUE(IF($H6="pří",$G6,0)) -> 0 | AJ6: =VALUE(IF($D6="dot",$C6,0))+VALUE(IF($H6="dot",$G6,0)) -> 0 | AK6: =VALUE(IF($D6="opř",$C6,0))+VALUE(IF($H6="opř",$G6,0)) -> 0 | AL6: =SUM(P6:AK6) -> 0 | AN6: =CONCATENATE("BÚ"," ",'Příjmy a výdaje'!$E6) -> BÚ | AO6: =IF('Příjmy a výdaje'!$G6="ano",'Příjmy a výdaje'!$B6,0) -> 0 | AP6: =IF('Příjmy a výdaje'!$G6="ano",'Příjmy a výdaje'!$C6,0) -> 0 | AQ6: ='Příjmy a výdaje'!$AP6 -> 0
A7: 2 | J7: =IF(AL7=C7,IF(AL7=0,"-","ok"),"chyba") -> - | P7: =VALUE(IF($D7="vyb",$C7,0))+VALUE(IF($H7="vyb",$G7,0)) -> 0 | Q7: =VALUE(IF($D7="mtv",$C7,0))+VALUE(IF($H7="mtv",$G7,0)) -> 0 | R7: =VALUE(IF($D7="mat",$C7,0))+VALUE(IF($H7="mat",$G7,0)) -> 0 | S7: =VALUE(IF($D7="pot",$C7,0))+VALUE(IF($H7="pot",$G7,0)) -> 0 | T7: =VALUE(IF($D7="táb",$C7,0))+VALUE(IF($H7="táb",$G7,0)) -> 0 | U7: =VALUE(IF($D7="oma",$C7,0))+VALUE(IF($H7="oma",$G7,0)) -> 0 | V7: =VALUE(IF($D7="ces",$C7,0))+VALUE(IF($H7="ces",$G7,0)) -> 0 | W7: =VALUE(IF($D7="poš",$C7,0))+VALUE(IF($H7="poš",$G7,0)) -> 0 | X7: =VALUE(IF($D7="tel",$C7,0))+VALUE(IF($H7="tel",$G7,0)) -> 0 | Y7: =VALUE(IF($D7="dop",$C7,0))+VALUE(IF($H7="dop",$G7,0)) -> 0 | Z7: =VALUE(IF($D7="nák",$C7,0))+VALUE(IF($H7="nák",$G7,0)) -> 0 | AA7: =VALUE(IF($D7="náj",$C7,0))+VALUE(IF($H7="náj",$G7,0)) -> 0 | AB7: =VALUE(IF($D7="půj",$C7,0))+VALUE(IF($H7="půj",$G7,0)) -> 0 | AC7: =VALUE(IF($D7="vst",$C7,0))+VALUE(IF($H7="vst",$G7,0)) -> 0 | AD7: =VALUE(IF($D7="kop",$C7,0))+VALUE(IF($H7="kop",$G7,0)) -> 0 | AE7: =VALUE(IF($D7="osl",$C7,0))+VALUE(IF($H7="osl",$G7,0)) -> 0 | AF7: =VALUE(IF($D7="vra",$C7,0))+VALUE(IF($H7="vra",$G7,0)) -> 0 | AG7: =VALUE(IF($D7="zho",$C7,0))+VALUE(IF($H7="zho",$G7,0)) -> 0 | AH7: =VALUE(IF($D7="zbú",$C7,0))+VALUE(IF($H7="zbú",$G7,0)) -> 0 | AI7: =VALUE(IF($D7="pří",$C7,0))+VALUE(IF($H7="pří",$G7,0)) -> 0 | AJ7: =VALUE(IF($D7="dot",$C7,0))+VALUE(IF($H7="dot",$G7,0)) -> 0 | AK7: =VALUE(IF($D7="opř",$C7,0))+VALUE(IF($H7="opř",$G7,0)) -> 0 | AL7: =SUM(P7:AK7) -> 0 | AN7: =CONCATENATE("BÚ"," ",'Příjmy a výdaje'!$E7) -> BÚ | AO7: =IF('Příjmy a výdaje'!$G7="ano",'Příjmy a výdaje'!$B7,0) -> 0 | AP7: =IF('Příjmy a výdaje'!$G7="ano",'Příjmy a výdaje'!$C7,0) -> 0 | AQ7: ='Příjmy a výdaje'!$AP7 -> 0
A8: 3 | J8: =IF(AL8=C8,IF(AL8=0,"-","ok"),"chyba") -> - | P8: =VALUE(IF($D8="vyb",$C8,0))+VALUE(IF($H8="vyb",$G8,0)) -> 0 | Q8: =VALUE(IF($D8="mtv",$C8,0))+VALUE(IF($H8="mtv",$G8,0)) -> 0 | R8: =VALUE(IF($D8="mat",$C8,0))+VALUE(IF($H8="mat",$G8,0)) -> 0 | S8: =VALUE(IF($D8="pot",$C8,0))+VALUE(IF($H8="pot",$G8,0)) -> 0 | T8: =VALUE(IF($D8="táb",$C8,0))+VALUE(IF($H8="táb",$G8,0)) -> 0 | U8: =VALUE(IF($D8="oma",$C8,0))+VALUE(IF($H8="oma",$G8,0)) -> 0 | V8: =VALUE(IF($D8="ces",$C8,0))+VALUE(IF($H8="ces",$G8,0)) -> 0 | W8: =VALUE(IF($D8="poš",$C8,0))+VALUE(IF($H8="poš",$G8,0)) -> 0 | X8: =VALUE(IF($D8="tel",$C8,0))+VALUE(IF($H8="tel",$G8,0)) -> 0 | Y8: =VALUE(IF($D8="dop",$C8,0))+VALUE(IF($H8="dop",$G8,0)) -> 0 | Z8: =VALUE(IF($D8="nák",$C8,0))+VALUE(IF($H8="nák",$G8,0)) -> 0 | AA8: =VALUE(IF($D8="náj",$C8,0))+VALUE(IF($H8="náj",$G8,0)) -> 0 | AB8: =VALUE(IF($D8="půj",$C8,0))+VALUE(IF($H8="půj",$G8,0)) -> 0 | AC8: =VALUE(IF($D8="vst",$C8,0))+VALUE(IF($H8="vst",$G8,0)) -> 0 | AD8: =VALUE(IF($D8="kop",$C8,0))+VALUE(IF($H8="kop",$G8,0)) -> 0 | AE8: =VALUE(IF($D8="osl",$C8,0))+VALUE(IF($H8="osl",$G8,0)) -> 0 | AF8: =VALUE(IF($D8="vra",$C8,0))+VALUE(IF($H8="vra",$G8,0)) -> 0 | AG8: =VALUE(IF($D8="zho",$C8,0))+VALUE(IF($H8="zho",$G8,0)) -> 0 | AH8: =VALUE(IF($D8="zbú",$C8,0))+VALUE(IF($H8="zbú",$G8,0)) -> 0 | AI8: =VALUE(IF($D8="pří",$C8,0))+VALUE(IF($H8="pří",$G8,0)) -> 0 | AJ8: =VALUE(IF($D8="dot",$C8,0))+VALUE(IF($H8="dot",$G8,0)) -> 0 | AK8: =VALUE(IF($D8="opř",$C8,0))+VALUE(IF($H8="opř",$G8,0)) -> 0 | AL8: =SUM(P8:AK8) -> 0 | AN8: =CONCATENATE("BÚ"," ",'Příjmy a výdaje'!$E8) -> BÚ | AO8: =IF('Příjmy a výdaje'!$G8="ano",'Příjmy a výdaje'!$B8,0) -> 0 | AP8: =IF('Příjmy a výdaje'!$G8="ano",'Příjmy a výdaje'!$C8,0) -> 0 | AQ8: ='Příjmy a výdaje'!$AP8 -> 0
A9: 4 | J9: =IF(AL9=C9,IF(AL9=0,"-","ok"),"chyba") -> - | P9: =VALUE(IF($D9="vyb",$C9,0))+VALUE(IF($H9="vyb",$G9,0)) -> 0 | Q9: =VALUE(IF($D9="mtv",$C9,0))+VALUE(IF($H9="mtv",$G9,0)) -> 0 | R9: =VALUE(IF($D9="mat",$C9,0))+VALUE(IF($H9="mat",$G9,0)) -> 0 | S9: =VALUE(IF($D9="pot",$C9,0))+VALUE(IF($H9="pot",$G9,0)) -> 0 | T9: =VALUE(IF($D9="táb",$C9,0))+VALUE(IF($H9="táb",$G9,0)) -> 0 | U9: =VALUE(IF($D9="oma",$C9,0))+VALUE(IF($H9="oma",$G9,0)) -> 0 | V9: =VALUE(IF($D9="ces",$C9,0))+VALUE(IF($H9="ces",$G9,0)) -> 0 | W9: =VALUE(IF($D9="poš",$C9,0))+VALUE(IF($H9="poš",$G9,0)) -> 0 | X9: =VALUE(IF($D9="tel",$C9,0))+VALUE(IF($H9="tel",$G9,0)) -> 0 | Y9: =VALUE(IF($D9="dop",$C9,0))+VALUE(IF($H9="dop",$G9,0)) -> 0 | Z9: =VALUE(IF($D9="nák",$C9,0))+VALUE(IF($H9="nák",$G9,0)) -> 0 | AA9: =VALUE(IF($D9="náj",$C9,0))+VALUE(IF($H9="náj",$G9,0)) -> 0 | AB9: =VALUE(IF($D9="půj",$C9,0))+VALUE(IF($H9="půj",$G9,0)) -> 0 | AC9: =VALUE(IF($D9="vst",$C9,0))+VALUE(IF($H9="vst",$G9,0)) -> 0 | AD9: =VALUE(IF($D9="kop",$C9,0))+VALUE(IF($H9="kop",$G9,0)) -> 0 | AE9: =VALUE(IF($D9="osl",$C9,0))+VALUE(IF($H9="osl",$G9,0)) -> 0 | AF9: =VALUE(IF($D9="vra",$C9,0))+VALUE(IF($H9="vra",$G9,0)) -> 0 | AG9: =VALUE(IF($D9="zho",$C9,0))+VALUE(IF($H9="zho",$G9,0)) -> 0 | AH9: =VALUE(IF($D9="zbú",$C9,0))+VALUE(IF($H9="zbú",$G9,0)) -> 0 | AI9: =VALUE(IF($D9="pří",$C9,0))+VALUE(IF($H9="pří",$G9,0)) -> 0 | AJ9: =VALUE(IF($D9="dot",$C9,0))+VALUE(IF($H9="dot",$G9,0)) -> 0 | AK9: =VALUE(IF($D9="opř",$C9,0))+VALUE(IF($H9="opř",$G9,0)) -> 0 | AL9: =SUM(P9:AK9) -> 0 | AN9: =CONCATENATE("BÚ"," ",'Příjmy a výdaje'!$E9) -> BÚ | AO9: =IF('Příjmy a výdaje'!$G9="ano",'Příjmy a výdaje'!$B9,0) -> 0 | AP9: =IF('Příjmy a výdaje'!$G9="ano",'Příjmy a výdaje'!$C9,0) -> 0 | AQ9: ='Příjmy a výdaje'!$AP9 -> 0
A10: 5 | J10: =IF(AL10=C10,IF(AL10=0,"-","ok"),"chyba") -> - | P10: =VALUE(IF($D10="vyb",$C10,0))+VALUE(IF($H10="vyb",$G10,0)) -> 0 | Q10: =VALUE(IF($D10="mtv",$C10,0))+VALUE(IF($H10="mtv",$G10,0)) -> 0 | R10: =VALUE(IF($D10="mat",$C10,0))+VALUE(IF($H10="mat",$G10,0)) -> 0 | S10: =VALUE(IF($D10="pot",$C10,0))+VALUE(IF($H10="pot",$G10,0)) -> 0 | T10: =VALUE(IF($D10="táb",$C10,0))+VALUE(IF($H10="táb",$G10,0)) -> 0 | U10: =VALUE(IF($D10="oma",$C10,0))+VALUE(IF($H10="oma",$G10,0)) -> 0 | V10: =VALUE(IF($D10="ces",$C10,0))+VALUE(IF($H10="ces",$G10,0)) -> 0 | W10: =VALUE(IF($D10="poš",$C10,0))+VALUE(IF($H10="poš",$G10,0)) -> 0 | X10: =VALUE(IF($D10="tel",$C10,0))+VALUE(IF($H10="tel",$G10,0)) -> 0 | Y10: =VALUE(IF($D10="dop",$C10,0))+VALUE(IF($H10="dop",$G10,0)) -> 0 | Z10: =VALUE(IF($D10="nák",$C10,0))+VALUE(IF($H10="nák",$G10,0)) -> 0 | AA10: =VALUE(IF($D10="náj",$C10,0))+VALUE(IF($H10="náj",$G10,0)) -> 0 | AB10: =VALUE(IF($D10="půj",$C10,0))+VALUE(IF($H10="půj",$G10,0)) -> 0 | AC10: =VALUE(IF($D10="vst",$C10,0))+VALUE(IF($H10="vst",$G10,0)) -> 0 | AD10: =VALUE(IF($D10="kop",$C10,0))+VALUE(IF($H10="kop",$G10,0)) -> 0 | AE10: =VALUE(IF($D10="osl",$C10,0))+VALUE(IF($H10="osl",$G10,0)) -> 0 | AF10: =VALUE(IF($D10="vra",$C10,0))+VALUE(IF($H10="vra",$G10,0)) -> 0 | AG10: =VALUE(IF($D10="zho",$C10,0))+VALUE(IF($H10="zho",$G10,0)) -> 0 | AH10: =VALUE(IF($D10="zbú",$C10,0))+VALUE(IF($H10="zbú",$G10,0)) -> 0 | AI10: =VALUE(IF($D10="pří",$C10,0))+VALUE(IF($H10="pří",$G10,0)) -> 0 | AJ10: =VALUE(IF($D10="dot",$C10,0))+VALUE(IF($H10="dot",$G10,0)) -> 0 | AK10: =VALUE(IF($D10="opř",$C10,0))+VALUE(IF($H10="opř",$G10,0)) -> 0 | AL10: =SUM(P10:AK10) -> 0 | AN10: =CONCATENATE("BÚ"," ",'Příjmy a výdaje'!$E10) -> BÚ | AO10: =IF('Příjmy a výdaje'!$G10="ano",'Příjmy a výdaje'!$B10,0) -> 0 | AP10: =IF('Příjmy a výdaje'!$G10="ano",'Příjmy a výdaje'!$C10,0) -> 0 | AQ10: ='Příjmy a výdaje'!$AP10 -> 0
A11: 6 | J11: =IF(AL11=C11,IF(AL11=0,"-","ok"),"chyba") -> - | P11: =VALUE(IF($D11="vyb",$C11,0))+VALUE(IF($H11="vyb",$G11,0)) -> 0 | Q11: =VALUE(IF($D11="mtv",$C11,0))+VALUE(IF($H11="mtv",$G11,0)) -> 0 | R11: =VALUE(IF($D11="mat",$C11,0))+VALUE(IF($H11="mat",$G11,0)) -> 0 | S11: =VALUE(IF($D11="pot",$C11,0))+VALUE(IF($H11="pot",$G11,0)) -> 0 | T11: =VALUE(IF($D11="táb",$C11,0))+VALUE(IF($H11="táb",$G11,0)) -> 0 | U11: =VALUE(IF($D11="oma",$C11,0))+VALUE(IF($H11="oma",$G11,0)) -> 0 | V11: =VALUE(IF($D11="ces",$C11,0))+VALUE(IF($H11="ces",$G11,0)) -> 0 | W11: =VALUE(IF($D11="poš",$C11,0))+VALUE(IF($H11="poš",$G11,0)) -> 0 | X11: =VALUE(IF($D11="tel",$C11,0))+VALUE(IF($H11="tel",$G11,0)) -> 0 | Y11: =VALUE(IF($D11="dop",$C11,0))+VALUE(IF($H11="dop",$G11,0)) -> 0 | Z11: =VALUE(IF($D11="nák",$C11,0))+VALUE(IF($H11="nák",$G11,0)) -> 0 | AA11: =VALUE(IF($D11="náj",$C11,0))+VALUE(IF($H11="náj",$G11,0)) -> 0 | AB11: =VALUE(IF($D11="půj",$C11,0))+VALUE(IF($H11="půj",$G11,0)) -> 0 | AC11: =VALUE(IF($D11="vst",$C11,0))+VALUE(IF($H11="vst",$G11,0)) -> 0 | AD11: =VALUE(IF($D11="kop",$C11,0))+VALUE(IF($H11="kop",$G11,0)) -> 0 | AE11: =VALUE(IF($D11="osl",$C11,0))+VALUE(IF($H11="osl",$G11,0)) -> 0 | AF11: =VALUE(IF($D11="vra",$C11,0))+VALUE(IF($H11="vra",$G11,0)) -> 0 | AG11: =VALUE(IF($D11="zho",$C11,0))+VALUE(IF($H11="zho",$G11,0)) -> 0 | AH11: =VALUE(IF($D11="zbú",$C11,0))+VALUE(IF($H11="zbú",$G11,0)) -> 0 | AI11: =VALUE(IF($D11="pří",$C11,0))+VALUE(IF($H11="pří",$G11,0)) -> 0 | AJ11: =VALUE(IF($D11="dot",$C11,0))+VALUE(IF($H11="dot",$G11,0)) -> 0 | AK11: =VALUE(IF($D11="opř",$C11,0))+VALUE(IF($H11="opř",$G11,0)) -> 0 | AL11: =SUM(P11:AK11) -> 0 | AN11: =CONCATENATE("BÚ"," ",'Příjmy a výdaje'!$E11) -> BÚ | AO11: =IF('Příjmy a výdaje'!$G11="ano",'Příjmy a výdaje'!$B11,0) -> 0 | AP11: =IF('Příjmy a výdaje'!$G11="ano",'Příjmy a výdaje'!$C11,0) -> 0 | AQ11: ='Příjmy a výdaje'!$AP11 -> 0
A12: 7 | J12: =IF(AL12=C12,IF(AL12=0,"-","ok"),"chyba") -> - | P12: =VALUE(IF($D12="vyb",$C12,0))+VALUE(IF($H12="vyb",$G12,0)) -> 0 | Q12: =VALUE(IF($D12="mtv",$C12,0))+VALUE(IF($H12="mtv",$G12,0)) -> 0 | R12: =VALUE(IF($D12="mat",$C12,0))+VALUE(IF($H12="mat",$G12,0)) -> 0 | S12: =VALUE(IF($D12="pot",$C12,0))+VALUE(IF($H12="pot",$G12,0)) -> 0 | T12: =VALUE(IF($D12="táb",$C12,0))+VALUE(IF($H12="táb",$G12,0)) -> 0 | U12: =VALUE(IF($D12="oma",$C12,0))+VALUE(IF($H12="oma",$G12,0)) -> 0 | V12: =VALUE(IF($D12="ces",$C12,0))+VALUE(IF($H12="ces",$G12,0)) -> 0 | W12: =VALUE(IF($D12="poš",$C12,0))+VALUE(IF($H12="poš",$G12,0)) -> 0 | X12: =VALUE(IF($D12="tel",$C12,0))+VALUE(IF($H12="tel",$G12,0)) -> 0 | Y12: =VALUE(IF($D12="dop",$C12,0))+VALUE(IF($H12="dop",$G12,0)) -> 0 | Z12: =VALUE(IF($D12="nák",$C12,0))+VALUE(IF($H12="nák",$G12,0)) -> 0 | AA12: =VALUE(IF($D12="náj",$C12,0))+VALUE(IF($H12="náj",$G12,0)) -> 0 | AB12: =VALUE(IF($D12="půj",$C12,0))+VALUE(IF($H12="půj",$G12,0)) -> 0 | AC12: =VALUE(IF($D12="vst",$C12,0))+VALUE(IF($H12="vst",$G12,0)) -> 0 | AD12: =VALUE(IF($D12="kop",$C12,0))+VALUE(IF($H12="kop",$G12,0)) -> 0 | AE12: =VALUE(IF($D12="osl",$C12,0))+VALUE(IF($H12="osl",$G12,0)) -> 0 | AF12: =VALUE(IF($D12="vra",$C12,0))+VALUE(IF($H12="vra",$G12,0)) -> 0 | AG12: =VALUE(IF($D12="zho",$C12,0))+VALUE(IF($H12="zho",$G12,0)) -> 0 | AH12: =VALUE(IF($D12="zbú",$C12,0))+VALUE(IF($H12="zbú",$G12,0)) -> 0 | AI12: =VALUE(IF($D12="pří",$C12,0))+VALUE(IF($H12="pří",$G12,0)) -> 0 | AJ12: =VALUE(IF($D12="dot",$C12,0))+VALUE(IF($H12="dot",$G12,0)) -> 0 | AK12: =VALUE(IF($D12="opř",$C12,0))+VALUE(IF($H12="opř",$G12,0)) -> 0 | AL12: =SUM(P12:AK12) -> 0 | AN12: =CONCATENATE("BÚ"," ",'Příjmy a výdaje'!$E12) -> BÚ | AO12: =IF('Příjmy a výdaje'!$G12="ano",'Příjmy a výdaje'!$B12,0) -> 0 | AP12: =IF('Příjmy a výdaje'!$G12="ano",'Příjmy a výdaje'!$C12,0) -> 0 | AQ12: ='Příjmy a výdaje'!$AP12 -> 0
A13: 8 | J13: =IF(AL13=C13,IF(AL13=0,"-","ok"),"chyba") -> - | P13: =VALUE(IF($D13="vyb",$C13,0))+VALUE(IF($H13="vyb",$G13,0)) -> 0 | Q13: =VALUE(IF($D13="mtv",$C13,0))+VALUE(IF($H13="mtv",$G13,0)) -> 0 | R13: =VALUE(IF($D13="mat",$C13,0))+VALUE(IF($H13="mat",$G13,0)) -> 0 | S13: =VALUE(IF($D13="pot",$C13,0))+VALUE(IF($H13="pot",$G13,0)) -> 0 | T13: =VALUE(IF($D13="táb",$C13,0))+VALUE(IF($H13="táb",$G13,0)) -> 0 | U13: =VALUE(IF($D13="oma",$C13,0))+VALUE(IF($H13="oma",$G13,0)) -> 0 | V13: =VALUE(IF($D13="ces",$C13,0))+VALUE(IF($H13="ces",$G13,0)) -> 0 | W13: =VALUE(IF($D13="poš",$C13,0))+VALUE(IF($H13="poš",$G13,0)) -> 0 | X13: =VALUE(IF($D13="tel",$C13,0))+VALUE(IF($H13="tel",$G13,0)) -> 0 | Y13: =VALUE(IF($D13="dop",$C13,0))+VALUE(IF($H13="dop",$G13,0)) -> 0 | Z13: =VALUE(IF($D13="nák",$C13,0))+VALUE(IF($H13="nák",$G13,0)) -> 0 | AA13: =VALUE(IF($D13="náj",$C13,0))+VALUE(IF($H13="náj",$G13,0)) -> 0 | AB13: =VALUE(IF($D13="půj",$C13,0))+VALUE(IF($H13="půj",$G13,0)) -> 0 | AC13: =VALUE(IF($D13="vst",$C13,0))+VALUE(IF($H13="vst",$G13,0)) -> 0 | AD13: =VALUE(IF($D13="kop",$C13,0))+VALUE(IF($H13="kop",$G13,0)) -> 0 | AE13: =VALUE(IF($D13="osl",$C13,0))+VALUE(IF($H13="osl",$G13,0)) -> 0 | AF13: =VALUE(IF($D13="vra",$C13,0))+VALUE(IF($H13="vra",$G13,0)) -> 0 | AG13: =VALUE(IF($D13="zho",$C13,0))+VALUE(IF($H13="zho",$G13,0)) -> 0 | AH13: =VALUE(IF($D13="zbú",$C13,0))+VALUE(IF($H13="zbú",$G13,0)) -> 0 | AI13: =VALUE(IF($D13="pří",$C13,0))+VALUE(IF($H13="pří",$G13,0)) -> 0 | AJ13: =VALUE(IF($D13="dot",$C13,0))+VALUE(IF($H13="dot",$G13,0)) -> 0 | AK13: =VALUE(IF($D13="opř",$C13,0))+VALUE(IF($H13="opř",$G13,0)) -> 0 | AL13: =SUM(P13:AK13) -> 0 | AN13: =CONCATENATE("BÚ"," ",'Příjmy a výdaje'!$E13) -> BÚ | AO13: =IF('Příjmy a výdaje'!$G13="ano",'Příjmy a výdaje'!$B13,0) -> 0 | AP13: =IF('Příjmy a výdaje'!$G13="ano",'Příjmy a výdaje'!$C13,0) -> 0 | AQ13: ='Příjmy a výdaje'!$AP13 -> 0
A14: 9 | J14: =IF(AL14=C14,IF(AL14=0,"-","ok"),"chyba") -> - | P14: =VALUE(IF($D14="vyb",$C14,0))+VALUE(IF($H14="vyb",$G14,0)) -> 0 | Q14: =VALUE(IF($D14="mtv",$C14,0))+VALUE(IF($H14="mtv",$G14,0)) -> 0 | R14: =VALUE(IF($D14="mat",$C14,0))+VALUE(IF($H14="mat",$G14,0)) -> 0 | S14: =VALUE(IF($D14="pot",$C14,0))+VALUE(IF($H14="pot",$G14,0)) -> 0 | T14: =VALUE(IF($D14="táb",$C14,0))+VALUE(IF($H14="táb",$G14,0)) -> 0 | U14: =VALUE(IF($D14="oma",$C14,0))+VALUE(IF($H14="oma",$G14,0)) -> 0 | V14: =VALUE(IF($D14="ces",$C14,0))+VALUE(IF($H14="ces",$G14,0)) -> 0 | W14: =VALUE(IF($D14="poš",$C14,0))+VALUE(IF($H14="poš",$G14,0)) -> 0 | X14: =VALUE(IF($D14="tel",$C14,0))+VALUE(IF($H14="tel",$G14,0)) -> 0 | Y14: =VALUE(IF($D14="dop",$C14,0))+VALUE(IF($H14="dop",$G14,0)) -> 0 | Z14: =VALUE(IF($D14="nák",$C14,0))+VALUE(IF($H14="nák",$G14,0)) -> 0 | AA14: =VALUE(IF($D14="náj",$C14,0))+VALUE(IF($H14="náj",$G14,0)) -> 0 | AB14: =VALUE(IF($D14="půj",$C14,0))+VALUE(IF($H14="půj",$G14,0)) -> 0 | AC14: =VALUE(IF($D14="vst",$C14,0))+VALUE(IF($H14="vst",$G14,0)) -> 0 | AD14: =VALUE(IF($D14="kop",$C14,0))+VALUE(IF($H14="kop",$G14,0)) -> 0 | AE14: =VALUE(IF($D14="osl",$C14,0))+VALUE(IF($H14="osl",$G14,0)) -> 0 | AF14: =VALUE(IF($D14="vra",$C14,0))+VALUE(IF($H14="vra",$G14,0)) -> 0 | AG14: =VALUE(IF($D14="zho",$C14,0))+VALUE(IF($H14="zho",$G14,0)) -> 0 | AH14: =VALUE(IF($D14="zbú",$C14,0))+VALUE(IF($H14="zbú",$G14,0)) -> 0 | AI14: =VALUE(IF($D14="pří",$C14,0))+VALUE(IF($H14="pří",$G14,0)) -> 0 | AJ14: =VALUE(IF($D14="dot",$C14,0))+VALUE(IF($H14="dot",$G14,0)) -> 0 | AK14: =VALUE(IF($D14="opř",$C14,0))+VALUE(IF($H14="opř",$G14,0)) -> 0 | AL14: =SUM(P14:AK14) -> 0 | AN14: =CONCATENATE("BÚ"," ",'Příjmy a výdaje'!$E14) -> BÚ | AO14: =IF('Příjmy a výdaje'!$G14="ano",'Příjmy a výdaje'!$B14,0) -> 0 | AP14: =IF('Příjmy a výdaje'!$G14="ano",'Příjmy a výdaje'!$C14,0) -> 0 | AQ14: ='Příjmy a výdaje'!$AP14 -> 0
A15: 10 | J15: =IF(AL15=C15,IF(AL15=0,"-","ok"),"chyba") -> - | P15: =VALUE(IF($D15="vyb",$C15,0))+VALUE(IF($H15="vyb",$G15,0)) -> 0 | Q15: =VALUE(IF($D15="mtv",$C15,0))+VALUE(IF($H15="mtv",$G15,0)) -> 0 | R15: =VALUE(IF($D15="mat",$C15,0))+VALUE(IF($H15="mat",$G15,0)) -> 0 | S15: =VALUE(IF($D15="pot",$C15,0))+VALUE(IF($H15="pot",$G15,0)) -> 0 | T15: =VALUE(IF($D15="táb",$C15,0))+VALUE(IF($H15="táb",$G15,0)) -> 0 | U15: =VALUE(IF($D15="oma",$C15,0))+VALUE(IF($H15="oma",$G15,0)) -> 0 | V15: =VALUE(IF($D15="ces",$C15,0))+VALUE(IF($H15="ces",$G15,0)) -> 0 | W15: =VALUE(IF($D15="poš",$C15,0))+VALUE(IF($H15="poš",$G15,0)) -> 0 | X15: =VALUE(IF($D15="tel",$C15,0))+VALUE(IF($H15="tel",$G15,0)) -> 0 | Y15: =VALUE(IF($D15="dop",$C15,0))+VALUE(IF($H15="dop",$G15,0)) -> 0 | Z15: =VALUE(IF($D15="nák",$C15,0))+VALUE(IF($H15="nák",$G15,0)) -> 0 | AA15: =VALUE(IF($D15="náj",$C15,0))+VALUE(IF($H15="náj",$G15,0)) -> 0 | AB15: =VALUE(IF($D15="půj",$C15,0))+VALUE(IF($H15="půj",$G15,0)) -> 0 | AC15: =VALUE(IF($D15="vst",$C15,0))+VALUE(IF($H15="vst",$G15,0)) -> 0 | AD15: =VALUE(IF($D15="kop",$C15,0))+VALUE(IF($H15="kop",$G15,0)) -> 0 | AE15: =VALUE(IF($D15="osl",$C15,0))+VALUE(IF($H15="osl",$G15,0)) -> 0 | AF15: =VALUE(IF($D15="vra",$C15,0))+VALUE(IF($H15="vra",$G15,0)) -> 0 | AG15: =VALUE(IF($D15="zho",$C15,0))+VALUE(IF($H15="zho",$G15,0)) -> 0 | AH15: =VALUE(IF($D15="zbú",$C15,0))+VALUE(IF($H15="zbú",$G15,0)) -> 0 | AI15: =VALUE(IF($D15="pří",$C15,0))+VALUE(IF($H15="pří",$G15,0)) -> 0 | AJ15: =VALUE(IF($D15="dot",$C15,0))+VALUE(IF($H15="dot",$G15,0)) -> 0 | AK15: =VALUE(IF($D15="opř",$C15,0))+VALUE(IF($H15="opř",$G15,0)) -> 0 | AL15: =SUM(P15:AK15) -> 0 | AN15: =CONCATENATE("BÚ"," ",'Příjmy a výdaje'!$E15) -> BÚ | AO15: =IF('Příjmy a výdaje'!$G15="ano",'Příjmy a výdaje'!$B15,0) -> 0 | AP15: =IF('Příjmy a výdaje'!$G15="ano",'Příjmy a výdaje'!$C15,0) -> 0 | AQ15: ='Příjmy a výdaje'!$AP15 -> 0
A16: 11 | J16: =IF(AL16=C16,IF(AL16=0,"-","ok"),"chyba") -> - | P16: =VALUE(IF($D16="vyb",$C16,0))+VALUE(IF($H16="vyb",$G16,0)) -> 0 | Q16: =VALUE(IF($D16="mtv",$C16,0))+VALUE(IF($H16="mtv",$G16,0)) -> 0 | R16: =VALUE(IF($D16="mat",$C16,0))+VALUE(IF($H16="mat",$G16,0)) -> 0 | S16: =VALUE(IF($D16="pot",$C16,0))+VALUE(IF($H16="pot",$G16,0)) -> 0 | T16: =VALUE(IF($D16="táb",$C16,0))+VALUE(IF($H16="táb",$G16,0)) -> 0 | U16: =VALUE(IF($D16="oma",$C16,0))+VALUE(IF($H16="oma",$G16,0)) -> 0 | V16: =VALUE(IF($D16="ces",$C16,0))+VALUE(IF($H16="ces",$G16,0)) -> 0 | W16: =VALUE(IF($D16="poš",$C16,0))+VALUE(IF($H16="poš",$G16,0)) -> 0 | X16: =VALUE(IF($D16="tel",$C16,0))+VALUE(IF($H16="tel",$G16,0)) -> 0 | Y16: =VALUE(IF($D16="dop",$C16,0))+VALUE(IF($H16="dop",$G16,0)) -> 0 | Z16: =VALUE(IF($D16="nák",$C16,0))+VALUE(IF($H16="nák",$G16,0)) -> 0 | AA16: =VALUE(IF($D16="náj",$C16,0))+VALUE(IF($H16="náj",$G16,0)) -> 0 | AB16: =VALUE(IF($D16="půj",$C16,0))+VALUE(IF($H16="půj",$G16,0)) -> 0 | AC16: =VALUE(IF($D16="vst",$C16,0))+VALUE(IF($H16="vst",$G16,0)) -> 0 | AD16: =VALUE(IF($D16="kop",$C16,0))+VALUE(IF($H16="kop",$G16,0)) -> 0 | AE16: =VALUE(IF($D16="osl",$C16,0))+VALUE(IF($H16="osl",$G16,0)) -> 0 | AF16: =VALUE(IF($D16="vra",$C16,0))+VALUE(IF($H16="vra",$G16,0)) -> 0 | AG16: =VALUE(IF($D16="zho",$C16,0))+VALUE(IF($H16="zho",$G16,0)) -> 0 | AH16: =VALUE(IF($D16="zbú",$C16,0))+VALUE(IF($H16="zbú",$G16,0)) -> 0 | AI16: =VALUE(IF($D16="pří",$C16,0))+VALUE(IF($H16="pří",$G16,0)) -> 0 | AJ16: =VALUE(IF($D16="dot",$C16,0))+VALUE(IF($H16="dot",$G16,0)) -> 0 | AK16: =VALUE(IF($D16="opř",$C16,0))+VALUE(IF($H16="opř",$G16,0)) -> 0 | AL16: =SUM(P16:AK16) -> 0 | AN16: =CONCATENATE("BÚ"," ",'Příjmy a výdaje'!$E16) -> BÚ | AO16: =IF('Příjmy a výdaje'!$G16="ano",'Příjmy a výdaje'!$B16,0) -> 0 | AP16: =IF('Příjmy a výdaje'!$G16="ano",'Příjmy a výdaje'!$C16,0) -> 0 | AQ16: ='Příjmy a výdaje'!$AP16 -> 0
A17: 12 | J17: =IF(AL17=C17,IF(AL17=0,"-","ok"),"chyba") -> - | P17: =VALUE(IF($D17="vyb",$C17,0))+VALUE(IF($H17="vyb",$G17,0)) -> 0 | Q17: =VALUE(IF($D17="mtv",$C17,0))+VALUE(IF($H17="mtv",$G17,0)) -> 0 | R17: =VALUE(IF($D17="mat",$C17,0))+VALUE(IF($H17="mat",$G17,0)) -> 0 | S17: =VALUE(IF($D17="pot",$C17,0))+VALUE(IF($H17="pot",$G17,0)) -> 0 | T17: =VALUE(IF($D17="táb",$C17,0))+VALUE(IF($H17="táb",$G17,0)) -> 0 | U17: =VALUE(IF($D17="oma",$C17,0))+VALUE(IF($H17="oma",$G17,0)) -> 0 | V17: =VALUE(IF($D17="ces",$C17,0))+VALUE(IF($H17="ces",$G17,0)) -> 0 | W17: =VALUE(IF($D17="poš",$C17,0))+VALUE(IF($H17="poš",$G17,0)) -> 0 | X17: =VALUE(IF($D17="tel",$C17,0))+VALUE(IF($H17="tel",$G17,0)) -> 0 | Y17: =VALUE(IF($D17="dop",$C17,0))+VALUE(IF($H17="dop",$G17,0)) -> 0 | Z17: =VALUE(IF($D17="nák",$C17,0))+VALUE(IF($H17="nák",$G17,0)) -> 0 | AA17: =VALUE(IF($D17="náj",$C17,0))+VALUE(IF($H17="náj",$G17,0)) -> 0 | AB17: =VALUE(IF($D17="půj",$C17,0))+VALUE(IF($H17="půj",$G17,0)) -> 0 | AC17: =VALUE(IF($D17="vst",$C17,0))+VALUE(IF($H17="vst",$G17,0)) -> 0 | AD17: =VALUE(IF($D17="kop",$C17,0))+VALUE(IF($H17="kop",$G17,0)) -> 0 | AE17: =VALUE(IF($D17="osl",$C17,0))+VALUE(IF($H17="osl",$G17,0)) -> 0 | AF17: =VALUE(IF($D17="vra",$C17,0))+VALUE(IF($H17="vra",$G17,0)) -> 0 | AG17: =VALUE(IF($D17="zho",$C17,0))+VALUE(IF($H17="zho",$G17,0)) -> 0 | AH17: =VALUE(IF($D17="zbú",$C17,0))+VALUE(IF($H17="zbú",$G17,0)) -> 0 | AI17: =VALUE(IF($D17="pří",$C17,0))+VALUE(IF($H17="pří",$G17,0)) -> 0 | AJ17: =VALUE(IF($D17="dot",$C17,0))+VALUE(IF($H17="dot",$G17,0)) -> 0 | AK17: =VALUE(IF($D17="opř",$C17,0))+VALUE(IF($H17="opř",$G17,0)) -> 0 | AL17: =SUM(P17:AK17) -> 0 | AN17: =CONCATENATE("BÚ"," ",'Příjmy a výdaje'!$E17) -> BÚ | AO17: =IF('Příjmy a výdaje'!$G17="ano",'Příjmy a výdaje'!$B17,0) -> 0 | AP17: =IF('Příjmy a výdaje'!$G17="ano",'Příjmy a výdaje'!$C17,0) -> 0 | AQ17: ='Příjmy a výdaje'!$AP17 -> 0
... A25: 20 | J25: =IF(AL25=C25,IF(AL25=0,"-","ok"),"chyba") -> - | P25: =VALUE(IF($D25="vyb",$C25,0))+VALUE(IF($H25="vyb",$G25,0)) -> 0 | Q25: =VALUE(IF($D25="mtv",$C25,0))+VALUE(IF($H25="mtv",$G25,0)) -> 0 | R25: =VALUE(IF($D25="mat",$C25,0))+VALUE(IF($H25="mat",$G25,0)) -> 0 | S25: =VALUE(IF($D25="pot",$C25,0))+VALUE(IF($H25="pot",$G25,0)) -> 0 | T25: =VALUE(IF($D25="táb",$C25,0))+VALUE(IF($H25="táb",$G25,0)) -> 0 | U25: =VALUE(IF($D25="oma",$C25,0))+VALUE(IF($H25="oma",$G25,0)) -> 0 | V25: =VALUE(IF($D25="ces",$C25,0))+VALUE(IF($H25="ces",$G25,0)) -> 0 | W25: =VALUE(IF($D25="poš",$C25,0))+VALUE(IF($H25="poš",$G25,0)) -> 0 | X25: =VALUE(IF($D25="tel",$C25,0))+VALUE(IF($H25="tel",$G25,0)) -> 0 | Y25: =VALUE(IF($D25="dop",$C25,0))+VALUE(IF($H25="dop",$G25,0)) -> 0 | Z25: =VALUE(IF($D25="nák",$C25,0))+VALUE(IF($H25="nák",$G25,0)) -> 0 | AA25: =VALUE(IF($D25="náj",$C25,0))+VALUE(IF($H25="náj",$G25,0)) -> 0 | AB25: =VALUE(IF($D25="půj",$C25,0))+VALUE(IF($H25="půj",$G25,0)) -> 0 | AC25: =VALUE(IF($D25="vst",$C25,0))+VALUE(IF($H25="vst",$G25,0)) -> 0 | AD25: =VALUE(IF($D25="kop",$C25,0))+VALUE(IF($H25="kop",$G25,0)) -> 0 | AE25: =VALUE(IF($D25="osl",$C25,0))+VALUE(IF($H25="osl",$G25,0)) -> 0 | AF25: =VALUE(IF($D25="vra",$C25,0))+VALUE(IF($H25="vra",$G25,0)) -> 0 | AG25: =VALUE(IF($D25="zho",$C25,0))+VALUE(IF($H25="zho",$G25,0)) -> 0 | AH25: =VALUE(IF($D25="zbú",$C25,0))+VALUE(IF($H25="zbú",$G25,0)) -> 0 | AI25: =VALUE(IF($D25="pří",$C25,0))+VALUE(IF($H25="pří",$G25,0)) -> 0 | AJ25: =VALUE(IF($D25="dot",$C25,0))+VALUE(IF($H25="dot",$G25,0)) -> 0 | AK25: =VALUE(IF($D25="opř",$C25,0))+VALUE(IF($H25="opř",$G25,0)) -> 0 | AL25: =SUM(P25:AK25) -> 0 | AN25: =CONCATENATE("BÚ"," ",'Příjmy a výdaje'!$E25) -> BÚ | AO25: =IF('Příjmy a výdaje'!$G25="ano",'Příjmy a výdaje'!$B25,0) -> 0 | AP25: =IF('Příjmy a výdaje'!$G25="ano",'Příjmy a výdaje'!$C25,0) -> 0 | AQ25: ='Příjmy a výdaje'!$AP25 -> 0
A26: 21 | J26: =IF(AL26=C26,IF(AL26=0,"-","ok"),"chyba") -> - | P26: =VALUE(IF($D26="vyb",$C26,0))+VALUE(IF($H26="vyb",$G26,0)) -> 0 | Q26: =VALUE(IF($D26="mtv",$C26,0))+VALUE(IF($H26="mtv",$G26,0)) -> 0 | R26: =VALUE(IF($D26="mat",$C26,0))+VALUE(IF($H26="mat",$G26,0)) -> 0 | S26: =VALUE(IF($D26="pot",$C26,0))+VALUE(IF($H26="pot",$G26,0)) -> 0 | T26: =VALUE(IF($D26="táb",$C26,0))+VALUE(IF($H26="táb",$G26,0)) -> 0 | U26: =VALUE(IF($D26="oma",$C26,0))+VALUE(IF($H26="oma",$G26,0)) -> 0 | V26: =VALUE(IF($D26="ces",$C26,0))+VALUE(IF($H26="ces",$G26,0)) -> 0 | W26: =VALUE(IF($D26="poš",$C26,0))+VALUE(IF($H26="poš",$G26,0)) -> 0 | X26: =VALUE(IF($D26="tel",$C26,0))+VALUE(IF($H26="tel",$G26,0)) -> 0 | Y26: =VALUE(IF($D26="dop",$C26,0))+VALUE(IF($H26="dop",$G26,0)) -> 0 | Z26: =VALUE(IF($D26="nák",$C26,0))+VALUE(IF($H26="nák",$G26,0)) -> 0 | AA26: =VALUE(IF($D26="náj",$C26,0))+VALUE(IF($H26="náj",$G26,0)) -> 0 | AB26: =VALUE(IF($D26="půj",$C26,0))+VALUE(IF($H26="půj",$G26,0)) -> 0 | AC26: =VALUE(IF($D26="vst",$C26,0))+VALUE(IF($H26="vst",$G26,0)) -> 0 | AD26: =VALUE(IF($D26="kop",$C26,0))+VALUE(IF($H26="kop",$G26,0)) -> 0 | AE26: =VALUE(IF($D26="osl",$C26,0))+VALUE(IF($H26="osl",$G26,0)) -> 0 | AF26: =VALUE(IF($D26="vra",$C26,0))+VALUE(IF($H26="vra",$G26,0)) -> 0 | AG26: =VALUE(IF($D26="zho",$C26,0))+VALUE(IF($H26="zho",$G26,0)) -> 0 | AH26: =VALUE(IF($D26="zbú",$C26,0))+VALUE(IF($H26="zbú",$G26,0)) -> 0 | AI26: =VALUE(IF($D26="pří",$C26,0))+VALUE(IF($H26="pří",$G26,0)) -> 0 | AJ26: =VALUE(IF($D26="dot",$C26,0))+VALUE(IF($H26="dot",$G26,0)) -> 0 | AK26: =VALUE(IF($D26="opř",$C26,0))+VALUE(IF($H26="opř",$G26,0)) -> 0 | AL26: =SUM(P26:AK26) -> 0
P27: =SUM(P6:P26) -> 0 | Q27: =SUM(Q6:Q26) -> 0 | R27: =SUM(R6:R26) -> 0 | S27: =SUM(S6:S26) -> 0 | T27: =SUM(T6:T26) -> 0 | U27: =SUM(U6:U26) -> 0 | V27: =SUM(V6:V26) -> 0 | W27: =SUM(W6:W26) -> 0 | ... AK27: =SUM(AK6:AK26) -> 0
B28: PŘEVODY MEZI POKLADNAMI / ZÁLOHY (přijaté i vracené)
B29: Položka | C29: Částka | D29: Kód | E29: Datum platby | F29: Způsob | G29: Komu | J29: Kontrola | P29: vyb | Q29: mtv | R29: mat | S29: pot | T29: táb | U29: oma | V29: ces | W29: poš | X29: tel | Y29: dop | Z29: nák | AA29: náj | AB29: půj | AC29: vst | AD29: kop | AE29: osl | AF29: vra | AG29: zho | AH29: zbú | AI29: pří | AJ29: dot | AK29: opř | AL29: součet
A30: 22 | J30: =IF(AL30=C30,IF(AL30=0,"-","ok"),"chyba") -> - | P30: =VALUE(IF($D30="vyb",$C30,0))+VALUE(IF($H30="vyb",$G30,0)) -> 0 | Q30: =VALUE(IF($D30="mtv",$C30,0))+VALUE(IF($H30="mtv",$G30,0)) -> 0 | R30: =VALUE(IF($D30="mat",$C30,0))+VALUE(IF($H30="mat",$G30,0)) -> 0 | S30: =VALUE(IF($D30="pot",$C30,0))+VALUE(IF($H30="pot",$G30,0)) -> 0 | T30: =VALUE(IF($D30="táb",$C30,0))+VALUE(IF($H30="táb",$G30,0)) -> 0 | U30: =VALUE(IF($D30="oma",$C30,0))+VALUE(IF($H30="oma",$G30,0)) -> 0 | V30: =VALUE(IF($D30="ces",$C30,0))+VALUE(IF($H30="ces",$G30,0)) -> 0 | W30: =VALUE(IF($D30="poš",$C30,0))+VALUE(IF($H30="poš",$G30,0)) -> 0 | X30: =VALUE(IF($D30="tel",$C30,0))+VALUE(IF($H30="tel",$G30,0)) -> 0 | Y30: =VALUE(IF($D30="dop",$C30,0))+VALUE(IF($H30="dop",$G30,0)) -> 0 | Z30: =VALUE(IF($D30="nák",$C30,0))+VALUE(IF($H30="nák",$G30,0)) -> 0 | AA30: =VALUE(IF($D30="náj",$C30,0))+VALUE(IF($H30="náj",$G30,0)) -> 0 | AB30: =VALUE(IF($D30="půj",$C30,0))+VALUE(IF($H30="půj",$G30,0)) -> 0 | AC30: =VALUE(IF($D30="vst",$C30,0))+VALUE(IF($H30="vst",$G30,0)) -> 0 | AD30: =VALUE(IF($D30="kop",$C30,0))+VALUE(IF($H30="kop",$G30,0)) -> 0 | AE30: =VALUE(IF($D30="osl",$C30,0))+VALUE(IF($H30="osl",$G30,0)) -> 0 | AF30: =VALUE(IF($D30="vra",$C30,0))+VALUE(IF($H30="vra",$G30,0)) -> 0 | AG30: =VALUE(IF($D30="zho",$C30,0))+VALUE(IF($H30="zho",$G30,0)) -> 0 | AH30: =VALUE(IF($D30="zbú",$C30,0))+VALUE(IF($H30="zbú",$G30,0)) -> 0 | AI30: =VALUE(IF($D30="pří",$C30,0))+VALUE(IF($H30="pří",$G30,0)) -> 0 | AJ30: =VALUE(IF($D30="dot",$C30,0))+VALUE(IF($H30="dot",$G30,0)) -> 0 | AK30: =VALUE(IF($D30="opř",$C30,0))+VALUE(IF($H30="opř",$G30,0)) -> 0 | AL30: =SUM(P30:AK30) -> 0
A31: 23 | J31: =IF(AL31=C31,IF(AL31=0,"-","ok"),"chyba") -> - | P31: =VALUE(IF($D31="vyb",$C31,0))+VALUE(IF($H31="vyb",$G31,0)) -> 0 | Q31: =VALUE(IF($D31="mtv",$C31,0))+VALUE(IF($H31="mtv",$G31,0)) -> 0 | R31: =VALUE(IF($D31="mat",$C31,0))+VALUE(IF($H31="mat",$G31,0)) -> 0 | S31: =VALUE(IF($D31="pot",$C31,0))+VALUE(IF($H31="pot",$G31,0)) -> 0 | T31: =VALUE(IF($D31="táb",$C31,0))+VALUE(IF($H31="táb",$G31,0)) -> 0 | U31: =VALUE(IF($D31="oma",$C31,0))+VALUE(IF($H31="oma",$G31,0)) -> 0 | V31: =VALUE(IF($D31="ces",$C31,0))+VALUE(IF($H31="ces",$G31,0)) -> 0 | W31: =VALUE(IF($D31="poš",$C31,0))+VALUE(IF($H31="poš",$G31,0)) -> 0 | X31: =VALUE(IF($D31="tel",$C31,0))+VALUE(IF($H31="tel",$G31,0)) -> 0 | Y31: =VALUE(IF($D31="dop",$C31,0))+VALUE(IF($H31="dop",$G31,0)) -> 0 | Z31: =VALUE(IF($D31="nák",$C31,0))+VALUE(IF($H31="nák",$G31,0)) -> 0 | AA31: =VALUE(IF($D31="náj",$C31,0))+VALUE(IF($H31="náj",$G31,0)) -> 0 | AB31: =VALUE(IF($D31="půj",$C31,0))+VALUE(IF($H31="půj",$G31,0)) -> 0 | AC31: =VALUE(IF($D31="vst",$C31,0))+VALUE(IF($H31="vst",$G31,0)) -> 0 | AD31: =VALUE(IF($D31="kop",$C31,0))+VALUE(IF($H31="kop",$G31,0)) -> 0 | AE31: =VALUE(IF($D31="osl",$C31,0))+VALUE(IF($H31="osl",$G31,0)) -> 0 | AF31: =VALUE(IF($D31="vra",$C31,0))+VALUE(IF($H31="vra",$G31,0)) -> 0 | AG31: =VALUE(IF($D31="zho",$C31,0))+VALUE(IF($H31="zho",$G31,0)) -> 0 | AH31: =VALUE(IF($D31="zbú",$C31,0))+VALUE(IF($H31="zbú",$G31,0)) -> 0 | AI31: =VALUE(IF($D31="pří",$C31,0))+VALUE(IF($H31="pří",$G31,0)) -> 0 | AJ31: =VALUE(IF($D31="dot",$C31,0))+VALUE(IF($H31="dot",$G31,0)) -> 0 | AK31: =VALUE(IF($D31="opř",$C31,0))+VALUE(IF($H31="opř",$G31,0)) -> 0 | AL31: =SUM(P31:AK31) -> 0
A32: 24 | J32: =IF(AL32=C32,IF(AL32=0,"-","ok"),"chyba") -> - | P32: =VALUE(IF($D32="vyb",$C32,0))+VALUE(IF($H32="vyb",$G32,0)) -> 0 | Q32: =VALUE(IF($D32="mtv",$C32,0))+VALUE(IF($H32="mtv",$G32,0)) -> 0 | R32: =VALUE(IF($D32="mat",$C32,0))+VALUE(IF($H32="mat",$G32,0)) -> 0 | S32: =VALUE(IF($D32="pot",$C32,0))+VALUE(IF($H32="pot",$G32,0)) -> 0 | T32: =VALUE(IF($D32="táb",$C32,0))+VALUE(IF($H32="táb",$G32,0)) -> 0 | U32: =VALUE(IF($D32="oma",$C32,0))+VALUE(IF($H32="oma",$G32,0)) -> 0 | V32: =VALUE(IF($D32="ces",$C32,0))+VALUE(IF($H32="ces",$G32,0)) -> 0 | W32: =VALUE(IF($D32="poš",$C32,0))+VALUE(IF($H32="poš",$G32,0)) -> 0 | X32: =VALUE(IF($D32="tel",$C32,0))+VALUE(IF($H32="tel",$G32,0)) -> 0 | Y32: =VALUE(IF($D32="dop",$C32,0))+VALUE(IF($H32="dop",$G32,0)) -> 0 | Z32: =VALUE(IF($D32="nák",$C32,0))+VALUE(IF($H32="nák",$G32,0)) -> 0 | AA32: =VALUE(IF($D32="náj",$C32,0))+VALUE(IF($H32="náj",$G32,0)) -> 0 | AB32: =VALUE(IF($D32="půj",$C32,0))+VALUE(IF($H32="půj",$G32,0)) -> 0 | AC32: =VALUE(IF($D32="vst",$C32,0))+VALUE(IF($H32="vst",$G32,0)) -> 0 | AD32: =VALUE(IF($D32="kop",$C32,0))+VALUE(IF($H32="kop",$G32,0)) -> 0 | AE32: =VALUE(IF($D32="osl",$C32,0))+VALUE(IF($H32="osl",$G32,0)) -> 0 | AF32: =VALUE(IF($D32="vra",$C32,0))+VALUE(IF($H32="vra",$G32,0)) -> 0 | AG32: =VALUE(IF($D32="zho",$C32,0))+VALUE(IF($H32="zho",$G32,0)) -> 0 | AH32: =VALUE(IF($D32="zbú",$C32,0))+VALUE(IF($H32="zbú",$G32,0)) -> 0 | AI32: =VALUE(IF($D32="pří",$C32,0))+VALUE(IF($H32="pří",$G32,0)) -> 0 | AJ32: =VALUE(IF($D32="dot",$C32,0))+VALUE(IF($H32="dot",$G32,0)) -> 0 | AK32: =VALUE(IF($D32="opř",$C32,0))+VALUE(IF($H32="opř",$G32,0)) -> 0 | AL32: =SUM(P32:AK32) -> 0
A33: 25 | J33: =IF(AL33=C33,IF(AL33=0,"-","ok"),"chyba") -> - | P33: =VALUE(IF($D33="vyb",$C33,0))+VALUE(IF($H33="vyb",$G33,0)) -> 0 | Q33: =VALUE(IF($D33="mtv",$C33,0))+VALUE(IF($H33="mtv",$G33,0)) -> 0 | R33: =VALUE(IF($D33="mat",$C33,0))+VALUE(IF($H33="mat",$G33,0)) -> 0 | S33: =VALUE(IF($D33="pot",$C33,0))+VALUE(IF($H33="pot",$G33,0)) -> 0 | T33: =VALUE(IF($D33="táb",$C33,0))+VALUE(IF($H33="táb",$G33,0)) -> 0 | U33: =VALUE(IF($D33="oma",$C33,0))+VALUE(IF($H33="oma",$G33,0)) -> 0 | V33: =VALUE(IF($D33="ces",$C33,0))+VALUE(IF($H33="ces",$G33,0)) -> 0 | W33: =VALUE(IF($D33="poš",$C33,0))+VALUE(IF($H33="poš",$G33,0)) -> 0 | X33: =VALUE(IF($D33="tel",$C33,0))+VALUE(IF($H33="tel",$G33,0)) -> 0 | Y33: =VALUE(IF($D33="dop",$C33,0))+VALUE(IF($H33="dop",$G33,0)) -> 0 | Z33: =VALUE(IF($D33="nák",$C33,0))+VALUE(IF($H33="nák",$G33,0)) -> 0 | AA33: =VALUE(IF($D33="náj",$C33,0))+VALUE(IF($H33="náj",$G33,0)) -> 0 | AB33: =VALUE(IF($D33="půj",$C33,0))+VALUE(IF($H33="půj",$G33,0)) -> 0 | AC33: =VALUE(IF($D33="vst",$C33,0))+VALUE(IF($H33="vst",$G33,0)) -> 0 | AD33: =VALUE(IF($D33="kop",$C33,0))+VALUE(IF($H33="kop",$G33,0)) -> 0 | AE33: =VALUE(IF($D33="osl",$C33,0))+VALUE(IF($H33="osl",$G33,0)) -> 0 | AF33: =VALUE(IF($D33="vra",$C33,0))+VALUE(IF($H33="vra",$G33,0)) -> 0 | AG33: =VALUE(IF($D33="zho",$C33,0))+VALUE(IF($H33="zho",$G33,0)) -> 0 | AH33: =VALUE(IF($D33="zbú",$C33,0))+VALUE(IF($H33="zbú",$G33,0)) -> 0 | AI33: =VALUE(IF($D33="pří",$C33,0))+VALUE(IF($H33="pří",$G33,0)) -> 0 | AJ33: =VALUE(IF($D33="dot",$C33,0))+VALUE(IF($H33="dot",$G33,0)) -> 0 | AK33: =VALUE(IF($D33="opř",$C33,0))+VALUE(IF($H33="opř",$G33,0)) -> 0 | AL33: =SUM(P33:AK33) -> 0
A34: 26 | J34: =IF(AL34=C34,IF(AL34=0,"-","ok"),"chyba") -> - | P34: =VALUE(IF($D34="vyb",$C34,0))+VALUE(IF($H34="vyb",$G34,0)) -> 0 | Q34: =VALUE(IF($D34="mtv",$C34,0))+VALUE(IF($H34="mtv",$G34,0)) -> 0 | R34: =VALUE(IF($D34="mat",$C34,0))+VALUE(IF($H34="mat",$G34,0)) -> 0 | S34: =VALUE(IF($D34="pot",$C34,0))+VALUE(IF($H34="pot",$G34,0)) -> 0 | T34: =VALUE(IF($D34="táb",$C34,0))+VALUE(IF($H34="táb",$G34,0)) -> 0 | U34: =VALUE(IF($D34="oma",$C34,0))+VALUE(IF($H34="oma",$G34,0)) -> 0 | V34: =VALUE(IF($D34="ces",$C34,0))+VALUE(IF($H34="ces",$G34,0)) -> 0 | W34: =VALUE(IF($D34="poš",$C34,0))+VALUE(IF($H34="poš",$G34,0)) -> 0 | X34: =VALUE(IF($D34="tel",$C34,0))+VALUE(IF($H34="tel",$G34,0)) -> 0 | Y34: =VALUE(IF($D34="dop",$C34,0))+VALUE(IF($H34="dop",$G34,0)) -> 0 | Z34: =VALUE(IF($D34="nák",$C34,0))+VALUE(IF($H34="nák",$G34,0)) -> 0 | AA34: =VALUE(IF($D34="náj",$C34,0))+VALUE(IF($H34="náj",$G34,0)) -> 0 | AB34: =VALUE(IF($D34="půj",$C34,0))+VALUE(IF($H34="půj",$G34,0)) -> 0 | AC34: =VALUE(IF($D34="vst",$C34,0))+VALUE(IF($H34="vst",$G34,0)) -> 0 | AD34: =VALUE(IF($D34="kop",$C34,0))+VALUE(IF($H34="kop",$G34,0)) -> 0 | AE34: =VALUE(IF($D34="osl",$C34,0))+VALUE(IF($H34="osl",$G34,0)) -> 0 | AF34: =VALUE(IF($D34="vra",$C34,0))+VALUE(IF($H34="vra",$G34,0)) -> 0 | AG34: =VALUE(IF($D34="zho",$C34,0))+VALUE(IF($H34="zho",$G34,0)) -> 0 | AH34: =VALUE(IF($D34="zbú",$C34,0))+VALUE(IF($H34="zbú",$G34,0)) -> 0 | AI34: =VALUE(IF($D34="pří",$C34,0))+VALUE(IF($H34="pří",$G34,0)) -> 0 | AJ34: =VALUE(IF($D34="dot",$C34,0))+VALUE(IF($H34="dot",$G34,0)) -> 0 | AK34: =VALUE(IF($D34="opř",$C34,0))+VALUE(IF($H34="opř",$G34,0)) -> 0 | AL34: =SUM(P34:AK34) -> 0
A35: 27 | J35: =IF(AL35=C35,IF(AL35=0,"-","ok"),"chyba") -> - | P35: =VALUE(IF($D35="vyb",$C35,0))+VALUE(IF($H35="vyb",$G35,0)) -> 0 | Q35: =VALUE(IF($D35="mtv",$C35,0))+VALUE(IF($H35="mtv",$G35,0)) -> 0 | R35: =VALUE(IF($D35="mat",$C35,0))+VALUE(IF($H35="mat",$G35,0)) -> 0 | S35: =VALUE(IF($D35="pot",$C35,0))+VALUE(IF($H35="pot",$G35,0)) -> 0 | T35: =VALUE(IF($D35="táb",$C35,0))+VALUE(IF($H35="táb",$G35,0)) -> 0 | U35: =VALUE(IF($D35="oma",$C35,0))+VALUE(IF($H35="oma",$G35,0)) -> 0 | V35: =VALUE(IF($D35="ces",$C35,0))+VALUE(IF($H35="ces",$G35,0)) -> 0 | W35: =VALUE(IF($D35="poš",$C35,0))+VALUE(IF($H35="poš",$G35,0)) -> 0 | X35: =VALUE(IF($D35="tel",$C35,0))+VALUE(IF($H35="tel",$G35,0)) -> 0 | Y35: =VALUE(IF($D35="dop",$C35,0))+VALUE(IF($H35="dop",$G35,0)) -> 0 | Z35: =VALUE(IF($D35="nák",$C35,0))+VALUE(IF($H35="nák",$G35,0)) -> 0 | AA35: =VALUE(IF($D35="náj",$C35,0))+VALUE(IF($H35="náj",$G35,0)) -> 0 | AB35: =VALUE(IF($D35="půj",$C35,0))+VALUE(IF($H35="půj",$G35,0)) -> 0 | AC35: =VALUE(IF($D35="vst",$C35,0))+VALUE(IF($H35="vst",$G35,0)) -> 0 | AD35: =VALUE(IF($D35="kop",$C35,0))+VALUE(IF($H35="kop",$G35,0)) -> 0 | AE35: =VALUE(IF($D35="osl",$C35,0))+VALUE(IF($H35="osl",$G35,0)) -> 0 | AF35: =VALUE(IF($D35="vra",$C35,0))+VALUE(IF($H35="vra",$G35,0)) -> 0 | AG35: =VALUE(IF($D35="zho",$C35,0))+VALUE(IF($H35="zho",$G35,0)) -> 0 | AH35: =VALUE(IF($D35="zbú",$C35,0))+VALUE(IF($H35="zbú",$G35,0)) -> 0 | AI35: =VALUE(IF($D35="pří",$C35,0))+VALUE(IF($H35="pří",$G35,0)) -> 0 | AJ35: =VALUE(IF($D35="dot",$C35,0))+VALUE(IF($H35="dot",$G35,0)) -> 0 | AK35: =VALUE(IF($D35="opř",$C35,0))+VALUE(IF($H35="opř",$G35,0)) -> 0 | AL35: =SUM(P35:AK35) -> 0
A36: 28 | J36: =IF(AL36=C36,IF(AL36=0,"-","ok"),"chyba") -> - | P36: =VALUE(IF($D36="vyb",$C36,0))+VALUE(IF($H36="vyb",$G36,0)) -> 0 | Q36: =VALUE(IF($D36="mtv",$C36,0))+VALUE(IF($H36="mtv",$G36,0)) -> 0 | R36: =VALUE(IF($D36="mat",$C36,0))+VALUE(IF($H36="mat",$G36,0)) -> 0 | S36: =VALUE(IF($D36="pot",$C36,0))+VALUE(IF($H36="pot",$G36,0)) -> 0 | T36: =VALUE(IF($D36="táb",$C36,0))+VALUE(IF($H36="táb",$G36,0)) -> 0 | U36: =VALUE(IF($D36="oma",$C36,0))+VALUE(IF($H36="oma",$G36,0)) -> 0 | V36: =VALUE(IF($D36="ces",$C36,0))+VALUE(IF($H36="ces",$G36,0)) -> 0 | W36: =VALUE(IF($D36="poš",$C36,0))+VALUE(IF($H36="poš",$G36,0)) -> 0 | X36: =VALUE(IF($D36="tel",$C36,0))+VALUE(IF($H36="tel",$G36,0)) -> 0 | Y36: =VALUE(IF($D36="dop",$C36,0))+VALUE(IF($H36="dop",$G36,0)) -> 0 | Z36: =VALUE(IF($D36="nák",$C36,0))+VALUE(IF($H36="nák",$G36,0)) -> 0 | AA36: =VALUE(IF($D36="náj",$C36,0))+VALUE(IF($H36="náj",$G36,0)) -> 0 | AB36: =VALUE(IF($D36="půj",$C36,0))+VALUE(IF($H36="půj",$G36,0)) -> 0 | AC36: =VALUE(IF($D36="vst",$C36,0))+VALUE(IF($H36="vst",$G36,0)) -> 0 | AD36: =VALUE(IF($D36="kop",$C36,0))+VALUE(IF($H36="kop",$G36,0)) -> 0 | AE36: =VALUE(IF($D36="osl",$C36,0))+VALUE(IF($H36="osl",$G36,0)) -> 0 | AF36: =VALUE(IF($D36="vra",$C36,0))+VALUE(IF($H36="vra",$G36,0)) -> 0 | AG36: =VALUE(IF($D36="zho",$C36,0))+VALUE(IF($H36="zho",$G36,0)) -> 0 | AH36: =VALUE(IF($D36="zbú",$C36,0))+VALUE(IF($H36="zbú",$G36,0)) -> 0 | AI36: =VALUE(IF($D36="pří",$C36,0))+VALUE(IF($H36="pří",$G36,0)) -> 0 | AJ36: =VALUE(IF($D36="dot",$C36,0))+VALUE(IF($H36="dot",$G36,0)) -> 0 | AK36: =VALUE(IF($D36="opř",$C36,0))+VALUE(IF($H36="opř",$G36,0)) -> 0 | AL36: =SUM(P36:AK36) -> 0
A37: 29 | J37: =IF(AL37=C37,IF(AL37=0,"-","ok"),"chyba") -> - | P37: =VALUE(IF($D37="vyb",$C37,0))+VALUE(IF($H37="vyb",$G37,0)) -> 0 | Q37: =VALUE(IF($D37="mtv",$C37,0))+VALUE(IF($H37="mtv",$G37,0)) -> 0 | R37: =VALUE(IF($D37="mat",$C37,0))+VALUE(IF($H37="mat",$G37,0)) -> 0 | S37: =VALUE(IF($D37="pot",$C37,0))+VALUE(IF($H37="pot",$G37,0)) -> 0 | T37: =VALUE(IF($D37="táb",$C37,0))+VALUE(IF($H37="táb",$G37,0)) -> 0 | U37: =VALUE(IF($D37="oma",$C37,0))+VALUE(IF($H37="oma",$G37,0)) -> 0 | V37: =VALUE(IF($D37="ces",$C37,0))+VALUE(IF($H37="ces",$G37,0)) -> 0 | W37: =VALUE(IF($D37="poš",$C37,0))+VALUE(IF($H37="poš",$G37,0)) -> 0 | X37: =VALUE(IF($D37="tel",$C37,0))+VALUE(IF($H37="tel",$G37,0)) -> 0 | Y37: =VALUE(IF($D37="dop",$C37,0))+VALUE(IF($H37="dop",$G37,0)) -> 0 | Z37: =VALUE(IF($D37="nák",$C37,0))+VALUE(IF($H37="nák",$G37,0)) -> 0 | AA37: =VALUE(IF($D37="náj",$C37,0))+VALUE(IF($H37="náj",$G37,0)) -> 0 | AB37: =VALUE(IF($D37="půj",$C37,0))+VALUE(IF($H37="půj",$G37,0)) -> 0 | AC37: =VALUE(IF($D37="vst",$C37,0))+VALUE(IF($H37="vst",$G37,0)) -> 0 | AD37: =VALUE(IF($D37="kop",$C37,0))+VALUE(IF($H37="kop",$G37,0)) -> 0 | AE37: =VALUE(IF($D37="osl",$C37,0))+VALUE(IF($H37="osl",$G37,0)) -> 0 | AF37: =VALUE(IF($D37="vra",$C37,0))+VALUE(IF($H37="vra",$G37,0)) -> 0 | AG37: =VALUE(IF($D37="zho",$C37,0))+VALUE(IF($H37="zho",$G37,0)) -> 0 | AH37: =VALUE(IF($D37="zbú",$C37,0))+VALUE(IF($H37="zbú",$G37,0)) -> 0 | AI37: =VALUE(IF($D37="pří",$C37,0))+VALUE(IF($H37="pří",$G37,0)) -> 0 | AJ37: =VALUE(IF($D37="dot",$C37,0))+VALUE(IF($H37="dot",$G37,0)) -> 0 | AK37: =VALUE(IF($D37="opř",$C37,0))+VALUE(IF($H37="opř",$G37,0)) -> 0 | AL37: =SUM(P37:AK37) -> 0
A38: 30 | J38: =IF(AL38=C38,IF(AL38=0,"-","ok"),"chyba") -> - | P38: =VALUE(IF($D38="vyb",$C38,0))+VALUE(IF($H38="vyb",$G38,0)) -> 0 | Q38: =VALUE(IF($D38="mtv",$C38,0))+VALUE(IF($H38="mtv",$G38,0)) -> 0 | R38: =VALUE(IF($D38="mat",$C38,0))+VALUE(IF($H38="mat",$G38,0)) -> 0 | S38: =VALUE(IF($D38="pot",$C38,0))+VALUE(IF($H38="pot",$G38,0)) -> 0 | T38: =VALUE(IF($D38="táb",$C38,0))+VALUE(IF($H38="táb",$G38,0)) -> 0 | U38: =VALUE(IF($D38="oma",$C38,0))+VALUE(IF($H38="oma",$G38,0)) -> 0 | V38: =VALUE(IF($D38="ces",$C38,0))+VALUE(IF($H38="ces",$G38,0)) -> 0 | W38: =VALUE(IF($D38="poš",$C38,0))+VALUE(IF($H38="poš",$G38,0)) -> 0 | X38: =VALUE(IF($D38="tel",$C38,0))+VALUE(IF($H38="tel",$G38,0)) -> 0 | Y38: =VALUE(IF($D38="dop",$C38,0))+VALUE(IF($H38="dop",$G38,0)) -> 0 | Z38: =VALUE(IF($D38="nák",$C38,0))+VALUE(IF($H38="nák",$G38,0)) -> 0 | AA38: =VALUE(IF($D38="náj",$C38,0))+VALUE(IF($H38="náj",$G38,0)) -> 0 | AB38: =VALUE(IF($D38="půj",$C38,0))+VALUE(IF($H38="půj",$G38,0)) -> 0 | AC38: =VALUE(IF($D38="vst",$C38,0))+VALUE(IF($H38="vst",$G38,0)) -> 0 | AD38: =VALUE(IF($D38="kop",$C38,0))+VALUE(IF($H38="kop",$G38,0)) -> 0 | AE38: =VALUE(IF($D38="osl",$C38,0))+VALUE(IF($H38="osl",$G38,0)) -> 0 | AF38: =VALUE(IF($D38="vra",$C38,0))+VALUE(IF($H38="vra",$G38,0)) -> 0 | AG38: =VALUE(IF($D38="zho",$C38,0))+VALUE(IF($H38="zho",$G38,0)) -> 0 | AH38: =VALUE(IF($D38="zbú",$C38,0))+VALUE(IF($H38="zbú",$G38,0)) -> 0 | AI38: =VALUE(IF($D38="pří",$C38,0))+VALUE(IF($H38="pří",$G38,0)) -> 0 | AJ38: =VALUE(IF($D38="dot",$C38,0))+VALUE(IF($H38="dot",$G38,0)) -> 0 | AK38: =VALUE(IF($D38="opř",$C38,0))+VALUE(IF($H38="opř",$G38,0)) -> 0 | AL38: =SUM(P38:AK38) -> 0
A39: 31 | J39: =IF(AL39=C39,IF(AL39=0,"-","ok"),"chyba") -> - | P39: =VALUE(IF($D39="vyb",$C39,0))+VALUE(IF($H39="vyb",$G39,0)) -> 0 | Q39: =VALUE(IF($D39="mtv",$C39,0))+VALUE(IF($H39="mtv",$G39,0)) -> 0 | R39: =VALUE(IF($D39="mat",$C39,0))+VALUE(IF($H39="mat",$G39,0)) -> 0 | S39: =VALUE(IF($D39="pot",$C39,0))+VALUE(IF($H39="pot",$G39,0)) -> 0 | T39: =VALUE(IF($D39="táb",$C39,0))+VALUE(IF($H39="táb",$G39,0)) -> 0 | U39: =VALUE(IF($D39="oma",$C39,0))+VALUE(IF($H39="oma",$G39,0)) -> 0 | V39: =VALUE(IF($D39="ces",$C39,0))+VALUE(IF($H39="ces",$G39,0)) -> 0 | W39: =VALUE(IF($D39="poš",$C39,0))+VALUE(IF($H39="poš",$G39,0)) -> 0 | X39: =VALUE(IF($D39="tel",$C39,0))+VALUE(IF($H39="tel",$G39,0)) -> 0 | Y39: =VALUE(IF($D39="dop",$C39,0))+VALUE(IF($H39="dop",$G39,0)) -> 0 | Z39: =VALUE(IF($D39="nák",$C39,0))+VALUE(IF($H39="nák",$G39,0)) -> 0 | AA39: =VALUE(IF($D39="náj",$C39,0))+VALUE(IF($H39="náj",$G39,0)) -> 0 | AB39: =VALUE(IF($D39="půj",$C39,0))+VALUE(IF($H39="půj",$G39,0)) -> 0 | AC39: =VALUE(IF($D39="vst",$C39,0))+VALUE(IF($H39="vst",$G39,0)) -> 0 | AD39: =VALUE(IF($D39="kop",$C39,0))+VALUE(IF($H39="kop",$G39,0)) -> 0 | AE39: =VALUE(IF($D39="osl",$C39,0))+VALUE(IF($H39="osl",$G39,0)) -> 0 | AF39: =VALUE(IF($D39="vra",$C39,0))+VALUE(IF($H39="vra",$G39,0)) -> 0 | AG39: =VALUE(IF($D39="zho",$C39,0))+VALUE(IF($H39="zho",$G39,0)) -> 0 | AH39: =VALUE(IF($D39="zbú",$C39,0))+VALUE(IF($H39="zbú",$G39,0)) -> 0 | AI39: =VALUE(IF($D39="pří",$C39,0))+VALUE(IF($H39="pří",$G39,0)) -> 0 | AJ39: =VALUE(IF($D39="dot",$C39,0))+VALUE(IF($H39="dot",$G39,0)) -> 0 | AK39: =VALUE(IF($D39="opř",$C39,0))+VALUE(IF($H39="opř",$G39,0)) -> 0 | AL39: =SUM(P39:AK39) -> 0
A40: 32 | J40: =IF(AL40=C40,IF(AL40=0,"-","ok"),"chyba") -> - | P40: =VALUE(IF($D40="vyb",$C40,0))+VALUE(IF($H40="vyb",$G40,0)) -> 0 | Q40: =VALUE(IF($D40="mtv",$C40,0))+VALUE(IF($H40="mtv",$G40,0)) -> 0 | R40: =VALUE(IF($D40="mat",$C40,0))+VALUE(IF($H40="mat",$G40,0)) -> 0 | S40: =VALUE(IF($D40="pot",$C40,0))+VALUE(IF($H40="pot",$G40,0)) -> 0 | T40: =VALUE(IF($D40="táb",$C40,0))+VALUE(IF($H40="táb",$G40,0)) -> 0 | U40: =VALUE(IF($D40="oma",$C40,0))+VALUE(IF($H40="oma",$G40,0)) -> 0 | V40: =VALUE(IF($D40="ces",$C40,0))+VALUE(IF($H40="ces",$G40,0)) -> 0 | W40: =VALUE(IF($D40="poš",$C40,0))+VALUE(IF($H40="poš",$G40,0)) -> 0 | X40: =VALUE(IF($D40="tel",$C40,0))+VALUE(IF($H40="tel",$G40,0)) -> 0 | Y40: =VALUE(IF($D40="dop",$C40,0))+VALUE(IF($H40="dop",$G40,0)) -> 0 | Z40: =VALUE(IF($D40="nák",$C40,0))+VALUE(IF($H40="nák",$G40,0)) -> 0 | AA40: =VALUE(IF($D40="náj",$C40,0))+VALUE(IF($H40="náj",$G40,0)) -> 0 | AB40: =VALUE(IF($D40="půj",$C40,0))+VALUE(IF($H40="půj",$G40,0)) -> 0 | AC40: =VALUE(IF($D40="vst",$C40,0))+VALUE(IF($H40="vst",$G40,0)) -> 0 | AD40: =VALUE(IF($D40="kop",$C40,0))+VALUE(IF($H40="kop",$G40,0)) -> 0 | AE40: =VALUE(IF($D40="osl",$C40,0))+VALUE(IF($H40="osl",$G40,0)) -> 0 | AF40: =VALUE(IF($D40="vra",$C40,0))+VALUE(IF($H40="vra",$G40,0)) -> 0 | AG40: =VALUE(IF($D40="zho",$C40,0))+VALUE(IF($H40="zho",$G40,0)) -> 0 | AH40: =VALUE(IF($D40="zbú",$C40,0))+VALUE(IF($H40="zbú",$G40,0)) -> 0 | AI40: =VALUE(IF($D40="pří",$C40,0))+VALUE(IF($H40="pří",$G40,0)) -> 0 | AJ40: =VALUE(IF($D40="dot",$C40,0))+VALUE(IF($H40="dot",$G40,0)) -> 0 | AK40: =VALUE(IF($D40="opř",$C40,0))+VALUE(IF($H40="opř",$G40,0)) -> 0 | AL40: =SUM(P40:AK40) -> 0
A41: 33 | J41: =IF(AL41=C41,IF(AL41=0,"-","ok"),"chyba") -> - | P41: =VALUE(IF($D41="vyb",$C41,0))+VALUE(IF($H41="vyb",$G41,0)) -> 0 | Q41: =VALUE(IF($D41="mtv",$C41,0))+VALUE(IF($H41="mtv",$G41,0)) -> 0 | R41: =VALUE(IF($D41="mat",$C41,0))+VALUE(IF($H41="mat",$G41,0)) -> 0 | S41: =VALUE(IF($D41="pot",$C41,0))+VALUE(IF($H41="pot",$G41,0)) -> 0 | T41: =VALUE(IF($D41="táb",$C41,0))+VALUE(IF($H41="táb",$G41,0)) -> 0 | U41: =VALUE(IF($D41="oma",$C41,0))+VALUE(IF($H41="oma",$G41,0)) -> 0 | V41: =VALUE(IF($D41="ces",$C41,0))+VALUE(IF($H41="ces",$G41,0)) -> 0 | W41: =VALUE(IF($D41="poš",$C41,0))+VALUE(IF($H41="poš",$G41,0)) -> 0 | X41: =VALUE(IF($D41="tel",$C41,0))+VALUE(IF($H41="tel",$G41,0)) -> 0 | Y41: =VALUE(IF($D41="dop",$C41,0))+VALUE(IF($H41="dop",$G41,0)) -> 0 | Z41: =VALUE(IF($D41="nák",$C41,0))+VALUE(IF($H41="nák",$G41,0)) -> 0 | AA41: =VALUE(IF($D41="náj",$C41,0))+VALUE(IF($H41="náj",$G41,0)) -> 0 | AB41: =VALUE(IF($D41="půj",$C41,0))+VALUE(IF($H41="půj",$G41,0)) -> 0 | AC41: =VALUE(IF($D41="vst",$C41,0))+VALUE(IF($H41="vst",$G41,0)) -> 0 | AD41: =VALUE(IF($D41="kop",$C41,0))+VALUE(IF($H41="kop",$G41,0)) -> 0 | AE41: =VALUE(IF($D41="osl",$C41,0))+VALUE(IF($H41="osl",$G41,0)) -> 0 | AF41: =VALUE(IF($D41="vra",$C41,0))+VALUE(IF($H41="vra",$G41,0)) -> 0 | AG41: =VALUE(IF($D41="zho",$C41,0))+VALUE(IF($H41="zho",$G41,0)) -> 0 | AH41: =VALUE(IF($D41="zbú",$C41,0))+VALUE(IF($H41="zbú",$G41,0)) -> 0 | AI41: =VALUE(IF($D41="pří",$C41,0))+VALUE(IF($H41="pří",$G41,0)) -> 0 | AJ41: =VALUE(IF($D41="dot",$C41,0))+VALUE(IF($H41="dot",$G41,0)) -> 0 | AK41: =VALUE(IF($D41="opř",$C41,0))+VALUE(IF($H41="opř",$G41,0)) -> 0 | AL41: =SUM(P41:AK41) -> 0
... A57: 49 | J57: =IF(AL57=C57,IF(AL57=0,"-","ok"),"chyba") -> - | P57: =VALUE(IF($D57="vyb",$C57,0))+VALUE(IF($H57="vyb",$G57,0)) -> 0 | Q57: =VALUE(IF($D57="mtv",$C57,0))+VALUE(IF($H57="mtv",$G57,0)) -> 0 | R57: =VALUE(IF($D57="mat",$C57,0))+VALUE(IF($H57="mat",$G57,0)) -> 0 | S57: =VALUE(IF($D57="pot",$C57,0))+VALUE(IF($H57="pot",$G57,0)) -> 0 | T57: =VALUE(IF($D57="táb",$C57,0))+VALUE(IF($H57="táb",$G57,0)) -> 0 | U57: =VALUE(IF($D57="oma",$C57,0))+VALUE(IF($H57="oma",$G57,0)) -> 0 | V57: =VALUE(IF($D57="ces",$C57,0))+VALUE(IF($H57="ces",$G57,0)) -> 0 | W57: =VALUE(IF($D57="poš",$C57,0))+VALUE(IF($H57="poš",$G57,0)) -> 0 | X57: =VALUE(IF($D57="tel",$C57,0))+VALUE(IF($H57="tel",$G57,0)) -> 0 | Y57: =VALUE(IF($D57="dop",$C57,0))+VALUE(IF($H57="dop",$G57,0)) -> 0 | Z57: =VALUE(IF($D57="nák",$C57,0))+VALUE(IF($H57="nák",$G57,0)) -> 0 | AA57: =VALUE(IF($D57="náj",$C57,0))+VALUE(IF($H57="náj",$G57,0)) -> 0 | AB57: =VALUE(IF($D57="půj",$C57,0))+VALUE(IF($H57="půj",$G57,0)) -> 0 | AC57: =VALUE(IF($D57="vst",$C57,0))+VALUE(IF($H57="vst",$G57,0)) -> 0 | AD57: =VALUE(IF($D57="kop",$C57,0))+VALUE(IF($H57="kop",$G57,0)) -> 0 | AE57: =VALUE(IF($D57="osl",$C57,0))+VALUE(IF($H57="osl",$G57,0)) -> 0 | AF57: =VALUE(IF($D57="vra",$C57,0))+VALUE(IF($H57="vra",$G57,0)) -> 0 | AG57: =VALUE(IF($D57="zho",$C57,0))+VALUE(IF($H57="zho",$G57,0)) -> 0 | AH57: =VALUE(IF($D57="zbú",$C57,0))+VALUE(IF($H57="zbú",$G57,0)) -> 0 | AI57: =VALUE(IF($D57="pří",$C57,0))+VALUE(IF($H57="pří",$G57,0)) -> 0 | AJ57: =VALUE(IF($D57="dot",$C57,0))+VALUE(IF($H57="dot",$G57,0)) -> 0 | AK57: =VALUE(IF($D57="opř",$C57,0))+VALUE(IF($H57="opř",$G57,0)) -> 0 | AL57: =SUM(P57:AK57) -> 0
P58: =VALUE(IF($D58="vyb",$C58,0))+VALUE(IF($H58="vyb",$G58,0)) -> 0 | Q58: =VALUE(IF($D58="mtv",$C58,0))+VALUE(IF($H58="mtv",$G58,0)) -> 0 | R58: =VALUE(IF($D58="mat",$C58,0))+VALUE(IF($H58="mat",$G58,0)) -> 0 | S58: =VALUE(IF($D58="pot",$C58,0))+VALUE(IF($H58="pot",$G58,0)) -> 0 | T58: =VALUE(IF($D58="táb",$C58,0))+VALUE(IF($H58="táb",$G58,0)) -> 0 | U58: =VALUE(IF($D58="oma",$C58,0))+VALUE(IF($H58="oma",$G58,0)) -> 0 | V58: =VALUE(IF($D58="ces",$C58,0))+VALUE(IF($H58="ces",$G58,0)) -> 0 | W58: =VALUE(IF($D58="poš",$C58,0))+VALUE(IF($H58="poš",$G58,0)) -> 0 | X58: =VALUE(IF($D58="tel",$C58,0))+VALUE(IF($H58="tel",$G58,0)) -> 0 | Y58: =VALUE(IF($D58="dop",$C58,0))+VALUE(IF($H58="dop",$G58,0)) -> 0 | Z58: =VALUE(IF($D58="nák",$C58,0))+VALUE(IF($H58="nák",$G58,0)) -> 0 | AA58: =VALUE(IF($D58="náj",$C58,0))+VALUE(IF($H58="náj",$G58,0)) -> 0 | AB58: =VALUE(IF($D58="půj",$C58,0))+VALUE(IF($H58="půj",$G58,0)) -> 0 | AC58: =VALUE(IF($D58="vst",$C58,0))+VALUE(IF($H58="vst",$G58,0)) -> 0 | AD58: =VALUE(IF($D58="kop",$C58,0))+VALUE(IF($H58="kop",$G58,0)) -> 0 | AE58: =VALUE(IF($D58="osl",$C58,0))+VALUE(IF($H58="osl",$G58,0)) -> 0 | AF58: =VALUE(IF($D58="vra",$C58,0))+VALUE(IF($H58="vra",$G58,0)) -> 0 | AG58: =VALUE(IF($D58="zho",$C58,0))+VALUE(IF($H58="zho",$G58,0)) -> 0 | AH58: =VALUE(IF($D58="zbú",$C58,0))+VALUE(IF($H58="zbú",$G58,0)) -> 0 | AI58: =VALUE(IF($D58="pří",$C58,0))+VALUE(IF($H58="pří",$G58,0)) -> 0 | AJ58: =VALUE(IF($D58="dot",$C58,0))+VALUE(IF($H58="dot",$G58,0)) -> 0 | AK58: =VALUE(IF($D58="opř",$C58,0))+VALUE(IF($H58="opř",$G58,0)) -> 0
B59: HOTOVOSTNÍ PŘÍJMY AKCE | P59: =VALUE(IF($D59="vyb",$C59,0))+VALUE(IF($H59="vyb",$G59,0)) -> 0 | Q59: =VALUE(IF($D59="mtv",$C59,0))+VALUE(IF($H59="mtv",$G59,0)) -> 0 | R59: =VALUE(IF($D59="mat",$C59,0))+VALUE(IF($H59="mat",$G59,0)) -> 0 | S59: =VALUE(IF($D59="pot",$C59,0))+VALUE(IF($H59="pot",$G59,0)) -> 0 | T59: =VALUE(IF($D59="táb",$C59,0))+VALUE(IF($H59="táb",$G59,0)) -> 0 | U59: =VALUE(IF($D59="oma",$C59,0))+VALUE(IF($H59="oma",$G59,0)) -> 0 | V59: =VALUE(IF($D59="ces",$C59,0))+VALUE(IF($H59="ces",$G59,0)) -> 0 | W59: =VALUE(IF($D59="poš",$C59,0))+VALUE(IF($H59="poš",$G59,0)) -> 0 | X59: =VALUE(IF($D59="tel",$C59,0))+VALUE(IF($H59="tel",$G59,0)) -> 0 | Y59: =VALUE(IF($D59="dop",$C59,0))+VALUE(IF($H59="dop",$G59,0)) -> 0 | Z59: =VALUE(IF($D59="nák",$C59,0))+VALUE(IF($H59="nák",$G59,0)) -> 0 | AA59: =VALUE(IF($D59="náj",$C59,0))+VALUE(IF($H59="náj",$G59,0)) -> 0 | AB59: =VALUE(IF($D59="půj",$C59,0))+VALUE(IF($H59="půj",$G59,0)) -> 0 | AC59: =VALUE(IF($D59="vst",$C59,0))+VALUE(IF($H59="vst",$G59,0)) -> 0 | AD59: =VALUE(IF($D59="kop",$C59,0))+VALUE(IF($H59="kop",$G59,0)) -> 0 | AE59: =VALUE(IF($D59="osl",$C59,0))+VALUE(IF($H59="osl",$G59,0)) -> 0 | AF59: =VALUE(IF($D59="vra",$C59,0))+VALUE(IF($H59="vra",$G59,0)) -> 0 | AG59: =VALUE(IF($D59="zho",$C59,0))+VALUE(IF($H59="zho",$G59,0)) -> 0 | AH59: =VALUE(IF($D59="zbú",$C59,0))+VALUE(IF($H59="zbú",$G59,0)) -> 0 | AI59: =VALUE(IF($D59="pří",$C59,0))+VALUE(IF($H59="pří",$G59,0)) -> 0 | AJ59: =VALUE(IF($D59="dot",$C59,0))+VALUE(IF($H59="dot",$G59,0)) -> 0 | AK59: =VALUE(IF($D59="opř",$C59,0))+VALUE(IF($H59="opř",$G59,0)) -> 0
B60: Položka | C60: Částka | D60: Kód | E60: Datum platby | F60: Poznámka | G60: Dotováno | J60: Kontrola | P60: =VALUE(IF($D60="vyb",$C60,0))+VALUE(IF($H60="vyb",$G60,0)) -> 0 | Q60: =VALUE(IF($D60="mtv",$C60,0))+VALUE(IF($H60="mtv",$G60,0)) -> 0 | R60: =VALUE(IF($D60="mat",$C60,0))+VALUE(IF($H60="mat",$G60,0)) -> 0 | S60: =VALUE(IF($D60="pot",$C60,0))+VALUE(IF($H60="pot",$G60,0)) -> 0 | T60: =VALUE(IF($D60="táb",$C60,0))+VALUE(IF($H60="táb",$G60,0)) -> 0 | U60: =VALUE(IF($D60="oma",$C60,0))+VALUE(IF($H60="oma",$G60,0)) -> 0 | V60: =VALUE(IF($D60="ces",$C60,0))+VALUE(IF($H60="ces",$G60,0)) -> 0 | W60: =VALUE(IF($D60="poš",$C60,0))+VALUE(IF($H60="poš",$G60,0)) -> 0 | X60: =VALUE(IF($D60="tel",$C60,0))+VALUE(IF($H60="tel",$G60,0)) -> 0 | Y60: =VALUE(IF($D60="dop",$C60,0))+VALUE(IF($H60="dop",$G60,0)) -> 0 | Z60: =VALUE(IF($D60="nák",$C60,0))+VALUE(IF($H60="nák",$G60,0)) -> 0 | AA60: =VALUE(IF($D60="náj",$C60,0))+VALUE(IF($H60="náj",$G60,0)) -> 0 | AB60: =VALUE(IF($D60="půj",$C60,0))+VALUE(IF($H60="půj",$G60,0)) -> 0 | AC60: =VALUE(IF($D60="vst",$C60,0))+VALUE(IF($H60="vst",$G60,0)) -> 0 | AD60: =VALUE(IF($D60="kop",$C60,0))+VALUE(IF($H60="kop",$G60,0)) -> 0 | AE60: =VALUE(IF($D60="osl",$C60,0))+VALUE(IF($H60="osl",$G60,0)) -> 0 | AF60: =VALUE(IF($D60="vra",$C60,0))+VALUE(IF($H60="vra",$G60,0)) -> 0 | AG60: =VALUE(IF($D60="zho",$C60,0))+VALUE(IF($H60="zho",$G60,0)) -> 0 | AH60: =VALUE(IF($D60="zbú",$C60,0))+VALUE(IF($H60="zbú",$G60,0)) -> 0 | AI60: =VALUE(IF($D60="pří",$C60,0))+VALUE(IF($H60="pří",$G60,0)) -> 0 | AJ60: =VALUE(IF($D60="dot",$C60,0))+VALUE(IF($H60="dot",$G60,0)) -> 0 | AK60: =VALUE(IF($D60="opř",$C60,0))+VALUE(IF($H60="opř",$G60,0)) -> 0 | AL60: součet
